Workbook

Sheet 属性分配
A1: 属性投放
C2: 基础属性 | H2: 基础属性-经营属性 | N2: 二级属性 | P2: 10000 = 1 | U2: FinalPct | V2: FinalPct | W2: FinalAdd
C3: 生命值 | D3: 外攻 | E3: 内攻 | F3: 外防 | G3: 内防 | H3: 农牧 | I3: 学识 | J3: 手工 | L3: 攻击速度 | N3: 暴击 | O3: 抗暴击 | P3: 命中 | Q3: 闪避 | R3: 暴击增伤 | S3: 暴击减伤 | T3: 增伤率 | U3: 增伤率 | V3: 护甲穿透率 | W3: 法术穿透率 | X3: 吸血 | Y3: 治疗率 | Z3: 受治疗率 | AA3: 招式冷却
B4: 基础属性 | C4: 300 | D4: 50 | E4: 50 | F4: 50 | G4: 50 | H4: 100 | I4: 100 | J4: 100 | L4: 1.5 | N4: 0 | O4: 0 | P4: 0 | Q4: 0 | R4: 0 | S4: 0
B5: 预期投放比例 | C5: =D5*2.5 -> 300 | D5: 120 | E5: 120 | F5: 80 | G5: 80 | H5: 12 | I5: 12 | J5: 12
B6: 预计最终属性 | C6: =C4*C5 -> 90000 | D6: =D4*D5 -> 6000 | E6: =E4*E5 -> 6000 | F6: =F4*F5 -> 4000 | G6: =G4*G5 -> 4000 | H6: =H4*H5 -> 1200 | I6: =I4*I5 -> 1200 | J6: =J4*J5 -> 1200 | N6: 6000 | O6: 6000 | P6: 6000 | Q6: 6000 | R6: 12000 | S6: 12000 | T6: 6000 | U6: 6000 | V6: 3000 | W6: 3000 | X6: 2000 | Y6: 4000 | Z6: 4000 | AA6: 3000
B7: 战力系数 | C7: 0.5 | D7: 4 | E7: 4 | F7: 2 | G7: 2 | H7: 1 | I7: 1 | J7: 1 | N7: 1 | O7: 1 | P7: 1 | Q7: 1 | R7: 0.5 | S7: 0.5 | V7: 2 | W7: 2 | X7: 2 | Y7: 2 | Z7: 2
B8: 战力计算 | C8: =C6*C7 -> 45000 | D8: =D6*D7 -> 24000 | E8: =E6*E7 -> 24000 | F8: =F6*F7 -> 8000 | G8: =G6*G7 -> 8000 | H8: =H6*H7 -> 1200 | I8: =I6*I7 -> 1200 | J8: =J6*J7 -> 1200
A10: 实际属性投放比
A11: 卡牌 | B11: 卡牌升级 | C11: 3 | D11: 3 | E11: 3 | F11: 2 | G11: 2 | H11: 1 | I11: 1 | J11: 1
B12: 卡牌突破 | C12: 3 | D12: 3 | E12: 3 | F12: 2 | G12: 2 | H12: 0 | I12: 0 | J12: 0
B13: 卡牌升星 | C13: 14 | D13: 7 | E13: 7 | F13: 5 | G13: 5 | H13: 1.5 | I13: 1.5 | J13: 1.5
B14: 突破实际投放属性
B15: 羁绊
A16: 装备 | B16: 基础属性 | C16: 8 | D16: 4 | E16: 4 | F16: 2 | G16: 2 | K16: 生命
B17: 装备强化 | C17: 24 | D17: 12 | E17: 12 | F17: 6 | G17: 6
B18: 装备进阶(升星) | C18: 0 | D18: 0 | E18: 0 | F18: 0 | G18: 0
B19: 属性洗练 | C19: =0.9*C16 -> 7.2 | D19: =0.9*D16 -> 3.6 | E19: =0.9*E16 -> 3.6 | F19: =0.9*F16 -> 1.8 | G19: =0.9*G16 -> 1.8 | N19: 1800 | O19: 1800 | P19: 1800 | Q19: 1800 | R19: 3600 | S19: 3600 | X19: 1500 | AA19: 1000
B20: 套装 | C20: =0.2*SUM(C16:C18) -> 6.4 | D20: =0.2*SUM(D16:D18) -> 3.2 | E20: =0.2*SUM(E16:E18) -> 3.2 | F20: =0.2*SUM(F16:F18) -> 1.6 | G20: =0.2*SUM(G16:G18) -> 1.6
A21: 其他 | B21: 藏经阁 | C21: =ROUND(0.6*(SUM(C11:C15)+1-C12),1) -> 10.8 | D21: =ROUND(0.6*(SUM(D11:D15)+1-D12),1) -> 6.6 | E21: =ROUND(0.6*(SUM(E11:E15)+1-E12),1) -> 6.6 | F21: =ROUND(0.6*(SUM(F11:F15)+1-F12),1) -> 4.8 | G21: =ROUND(0.6*(SUM(G11:G15)+1-G12),1) -> 4.8 | H21: 3 | I21: 3 | J21: 3
B22: 联盟 | C22: 0 | D22: 0 | E22: 0 | F22: 0 | G22: 0 | N22: 1500 | O22: 1500 | P22: 1500 | Q22: 1500 | R22: 3000 | S22: 3000 | T22: 1500 | U22: 1500 | Y22: 1500 | Z22: 1500
B23: 坐骑
B24: 神兵 | C24: 0 | D24: =(SUM(D11:D15)+1)*0.3 -> 4.2 | E24: =(SUM(E11:E15)+1)*0.3 -> 4.2 | F24: 0 | G24: 0 | N24: 1000 | O24: 1000 | P24: 1000 | Q24: 1000 | R24: 2000 | S24: 2000 | T24: 1000 | V24: 1000 | W24: 1000 | Y24: 2000 | Z24: 2000 | AA24: 2000
B25: 名号（声望） | C25: 0 | D25: 0 | E25: 0 | F25: 0 | G25: 0
B26: 友人 | C26: 0 | D26: 0 | E26: 0 | F26: 0 | G26: 0
B27: 宝物 | C27: 0 | D27: 0 | E27: 0 | F27: 0 | G27: 0 | H27: 0 | I27: 0 | J27: 0
A28: 总计 | B28: 总计-投放比 | C28: =SUM(C11:C27)+1-C12 -> 74.4 | D28: =SUM(D11:D27)+1-D12 -> 44.6 | E28: =SUM(E11:E27)+1-E12 -> 44.6 | F28: =SUM(F11:F27)+1-F12 -> 24.2 | G28: =SUM(G11:G27)+1-G12 -> 24.2 | H28: =SUM(H11:H27)+1 -> 6.5 | I28: =SUM(I11:I27)+1 -> 6.5 | J28: =SUM(J11:J27)+1 -> 6.5
B29: 总计 | C29: =C28*C4 -> 22320 | D29: =D28*D4 -> 2230 | E29: =E28*E4 -> 2230 | F29: =F28*F4 -> 1210 | G29: =G28*G4 -> 1210 | H29: =H28*H4 -> 650 | I29: =I28*I4 -> 650 | J29: =J28*J4 -> 650
B30: 攻血比 | C30: =ROUND(C29/D29,5) -> 10.00897
B32: 战力统计 | C32: =C29*C7 -> 11160 | D32: =D29*D7 -> 8920 | E32: =E29*E7 -> 8920 | F32: =F29*F7 -> 2420 | G32: =G29*G7 -> 2420 | H32: =H29*H7 -> 650 | I32: =I29*I7 -> 650 | J32: =J29*J7 -> 650 | K32: =J29*J7 -> 650
C33: =C32+MAX(D32,E32)+AVERAGE(F32:G32)+H32 -> 23150
B35: 面板属性： | C35: (弟子属性+弟子等级*弟子成长属性+升阶提升比)*(1+卡牌升星)*(1+科技加成比例)+（装备基础属性+装备等级*装备成长属性)*（1+套装加成比例+属性洗练比例）+被动技能固定值+宝物固定属性+门派藏经阁固定属性
C36: (base+baseAdd)*(1+basePct)*(1+FinalPct)+FinalAdd
C37: base | E37: 弟子原始属性
C38: baseAdd | E38: 弟子升级所增加的属性，弟子突破进阶
C39: basePct | E39: 升星附加的属性
C40: FinalPct | E40: 属性增益，比如科技加成比例等类似的加成
C41: FinalAdd | E41: 增加的固定属性，比如装备增加的这种属性
A43: 战斗计算流程
F44: 战斗中属性 | G44: 面板属性*（1+阵营属性加成+buff属性）
...

Sheet 职业模板
C2: 300 | D2: 50 | E2: 50 | F2: 50 | G2: 50 | H2: 100 | I2: 100 | J2: 100
B3: 模板系数 | C3: 生命值 | D3: 外攻 | E3: 内攻 | F3: 外防 | G3: 内防 | H3: 农牧 | I3: 学识 | J3: 手工 | M3: 基础属性 | N3: 生命值 | O3: 外攻 | P3: 内攻 | Q3: 外防 | R3: 内防 | S3: 农牧 | T3: 学识 | U3: 手工 | W3: 战力 | Y3: 攻击max
B4: 标准模板 | C4: 1 | D4: 1 | E4: 1 | F4: 1 | G4: 1 | H4: 1 | I4: 1 | J4: 1 | M4: 标准模板 | N4: {=INDEX(属性分配!$C$4:$J$4,MATCH(N$3,属性分配!$C$3:$J$3,FALSE))} -> 300 | O4: {=INDEX(属性分配!$C$4:$J$4,MATCH(O$3,属性分配!$C$3:$J$3,FALSE))} -> 50 | P4: {=INDEX(属性分配!$C$4:$J$4,MATCH(P$3,属性分配!$C$3:$J$3,FALSE))} -> 50 | Q4: {=INDEX(属性分配!$C$4:$J$4,MATCH(Q$3,属性分配!$C$3:$J$3,FALSE))} -> 50 | R4: {=INDEX(属性分配!$C$4:$J$4,MATCH(R$3,属性分配!$C$3:$J$3,FALSE))} -> 50 | S4: {=INDEX(属性分配!$C$4:$J$4,MATCH(S$3,属性分配!$C$3:$J$3,FALSE))} -> 100 | T4: {=INDEX(属性分配!$C$4:$J$4,MATCH(T$3,属性分配!$C$3:$J$3,FALSE))} -> 100 | U4: {=INDEX(属性分配!$C$4:$J$4,MATCH(U$3,属性分配!$C$3:$J$3,FALSE))} -> 100 | W4: {=SUMPRODUCT(N4:R4,C$14:G$14)} -> 750 | Y4: =MAX(O4:P4) -> 50
B5: 坦克 | C5: 1.35 | D5: 0.8 | E5: 0.75 | F5: 1.2 | G5: 0.8 | H5: 0.6 | I5: 0.6 | J5: 0.6 | M5: 坦克 | N5: =C5*N$4 -> 405 | O5: =D5*O$4 -> 40 | P5: =E5*P$4 -> 37.5 | Q5: =F5*Q$4 -> 60 | R5: =G5*R$4 -> 40 | S5: =H5*S$4 -> 60 | T5: =I5*T$4 -> 60 | U5: =J5*U$4 -> 60 | W5: {=SUMPRODUCT(N5:R5,C$14:G$14)} -> 712.5 | Y5: =MAX(O5:P5) -> 40
B6: 战士 | C6: 1.05 | D6: 1.1 | E6: 0.8 | F6: 1 | G6: 0.95 | H6: 0.7 | I6: 0.5 | J6: 0.6 | M6: 战士 | N6: =C6*N$4 -> 315 | O6: =D6*O$4 -> 55 | P6: =E6*P$4 -> 40 | Q6: =F6*Q$4 -> 50 | R6: =G6*R$4 -> 47.5 | S6: =H6*S$4 -> 70 | T6: =I6*T$4 -> 50 | U6: =J6*U$4 -> 60 | W6: {=SUMPRODUCT(N6:R6,C$14:G$14)} -> 732.5 | Y6: =MAX(O6:P6) -> 55
B7: 法坦 | C7: 1.3 | D7: 0.75 | E7: 0.8 | F7: 0.95 | G7: 1.2 | H7: 0.5 | I7: 0.7 | J7: 0.6 | M7: 法坦 | N7: =C7*N$4 -> 390 | O7: =D7*O$4 -> 37.5 | P7: =E7*P$4 -> 40 | Q7: =F7*Q$4 -> 47.5 | R7: =G7*R$4 -> 60 | S7: =H7*S$4 -> 50 | T7: =I7*T$4 -> 70 | U7: =J7*U$4 -> 60 | W7: {=SUMPRODUCT(N7:R7,C$14:G$14)} -> 720 | Y7: =MAX(O7:P7) -> 40
B8: 刺客 | C8: 0.9 | D8: 1.2 | E8: 0.9 | F8: 0.9 | G8: 0.9 | H8: 0.5 | I8: 0.6 | J8: 0.7 | M8: 刺客 | N8: =C8*N$4 -> 270 | O8: =D8*O$4 -> 60 | P8: =E8*P$4 -> 45 | Q8: =F8*Q$4 -> 45 | R8: =G8*R$4 -> 45 | S8: =H8*S$4 -> 50 | T8: =I8*T$4 -> 60 | U8: =J8*U$4 -> 70 | W8: {=SUMPRODUCT(N8:R8,C$14:G$14)} -> 735 | Y8: =MAX(O8:P8) -> 60
B9: 魔剑士 | C9: 1 | D9: 0.9 | E9: 1.1 | F9: 0.9 | G9: 0.9 | H9: 0.6 | I9: 0.7 | J9: 0.5 | M9: 魔剑士 | N9: =C9*N$4 -> 300 | O9: =D9*O$4 -> 45 | P9: =E9*P$4 -> 55 | Q9: =F9*Q$4 -> 45 | R9: =G9*R$4 -> 45 | S9: =H9*S$4 -> 60 | T9: =I9*T$4 -> 70 | U9: =J9*U$4 -> 50 | W9: {=SUMPRODUCT(N9:R9,C$14:G$14)} -> 730 | Y9: =MAX(O9:P9) -> 55
B10: 法师 | C10: 0.9 | D10: 0.85 | E10: 1.25 | F10: 0.75 | G10: 1.05 | H10: 0.5 | I10: 0.8 | J10: 0.5 | M10: 法师 | N10: =C10*N$4 -> 270 | O10: =D10*O$4 -> 42.5 | P10: =E10*P$4 -> 62.5 | Q10: =F10*Q$4 -> 37.5 | R10: =G10*R$4 -> 52.5 | S10: =H10*S$4 -> 50 | T10: =I10*T$4 -> 80 | U10: =J10*U$4 -> 50 | W10: {=SUMPRODUCT(N10:R10,C$14:G$14)} -> 735 | Y10: =MAX(O10:P10) -> 62.5
B11: 猎人 | C11: 0.95 | D11: 1.2 | E11: 0.8 | F11: 0.95 | G11: 0.9 | H11: 0.7 | I11: 0.5 | J11: 0.6 | M11: 猎人 | N11: =C11*N$4 -> 285 | O11: =D11*O$4 -> 60 | P11: =E11*P$4 -> 40 | Q11: =F11*Q$4 -> 47.5 | R11: =G11*R$4 -> 45 | S11: =H11*S$4 -> 70 | T11: =I11*T$4 -> 50 | U11: =J11*U$4 -> 60 | W11: {=SUMPRODUCT(N11:R11,C$14:G$14)} -> 727.5 | Y11: =MAX(O11:P11) -> 60
B12: 辅助 | C12: 1.1 | D12: 0.9 | E12: 1 | F12: 0.95 | G12: 0.95 | H12: 0.6 | I12: 0.5 | J12: 0.7 | M12: 辅助 | N12: =C12*N$4 -> 330 | O12: =D12*O$4 -> 45 | P12: =E12*P$4 -> 50 | Q12: =F12*Q$4 -> 47.5 | R12: =G12*R$4 -> 47.5 | S12: =H12*S$4 -> 60 | T12: =I12*T$4 -> 50 | U12: =J12*U$4 -> 70 | W12: {=SUMPRODUCT(N12:R12,C$14:G$14)} -> 735 | Y12: =MAX(O12:P12) -> 50
B14: 属性战力 | C14: =属性分配!C7 -> 0.5 | D14: =属性分配!D7 -> 4 | E14: =属性分配!E7 -> 4 | F14: =属性分配!F7 -> 2 | G14: =属性分配!G7 -> 2 | H14: 1 | I14: 1 | J14: 1
B16: 成长属性 | D16: 等级上限 | E16: 100 | M16: 战斗回合模拟 - 初级模拟(排除防御),红色为攻击方
C17: 生命值 | D17: 外攻 | E17: 内攻 | F17: 外防 | G17: 内防 | H17: 农牧 | I17: 学识 | J17: 手工 | K17: 战斗力-升级 | N17: 标准模板 | O17: 坦克 | P17: 战士 | Q17: 法坦 | R17: 刺客 | S17: 魔剑士 | T17: 法师 | U17: 猎人
B18: 标准模板 | C18: {=属性分配!C$11*属性分配!C$4/$E$16*INDEX($C$4:$J$12,MATCH($B18,$B$4:$B$12,FALSE),MATCH(C$17,$C$3:$J$3,FALSE))} -> 9 | D18: {=属性分配!D$11*属性分配!D$4/$E$16*INDEX($C$4:$J$12,MATCH($B18,$B$4:$B$12,FALSE),MATCH(D$17,$C$3:$J$3,FALSE))} -> 1.5 | E18: {=属性分配!E$11*属性分配!E$4/$E$16*INDEX($C$4:$J$12,MATCH($B18,$B$4:$B$12,FALSE),MATCH(E$17,$C$3:$J$3,FALSE))} -> 1.5 | F18: {=属性分配!F$11*属性分配!F$4/$E$16*INDEX($C$4:$J$12,MATCH($B18,$B$4:$B$12,FALSE),MATCH(F$17,$C$3:$J$3,FALSE))} -> 1 | G18: {=属性分配!G$11*属性分配!G$4/$E$16*INDEX($C$4:$J$12,MATCH($B18,$B$4:$B$12,FALSE),MATCH(G$17,$C$3:$J$3,FALSE))} -> 1 | H18: {=属性分配!H$11*属性分配!H$4/$E$16*INDEX($C$4:$J$12,MATCH($B18,$B$4:$B$12,FALSE),MATCH(H$17,$C$3:$J$3,FALSE))} -> 1 | I18: {=属性分配!I$11*属性分配!I$4/$E$16*INDEX($C$4:$J$12,MATCH($B18,$B$4:$B$12,FALSE),MATCH(I$17,$C$3:$J$3,FALSE))} -> 1 | J18: {=属性分配!J$11*属性分配!J$4/$E$16*INDEX($C$4:$J$12,MATCH($B18,$B$4:$B$12,FALSE),MATCH(J$17,$C$3:$J$3,FALSE))} -> 1 | K18: {=SUMPRODUCT($C18:$G18,$C$14:$G$14)} -> 20.5 | M18: 标准模板 | N18: {=ROUND(INDEX($N$4:$N$12,MATCH($M18,$M$4:$M$12,FALSE))/INDEX($Y$4:$Y$12,MATCH(N$17,$M$4:$M$12,FALSE)),2)} -> 6 | O18: {=ROUND(INDEX($N$4:$N$12,MATCH($M18,$M$4:$M$12,FALSE))/INDEX($Y$4:$Y$12,MATCH(O$17,$M$4:$M$12,FALSE)),2)} -> 7.5 | P18: {=ROUND(INDEX($N$4:$N$12,MATCH($M18,$M$4:$M$12,FALSE))/INDEX($Y$4:$Y$12,MATCH(P$17,$M$4:$M$12,FALSE)),2)} -> 5.45 | Q18: {=ROUND(INDEX($N$4:$N$12,MATCH($M18,$M$4:$M$12,FALSE))/INDEX($Y$4:$Y$12,MATCH(Q$17,$M$4:$M$12,FALSE)),2)} -> 7.5 | R18: {=ROUND(INDEX($N$4:$N$12,MATCH($M18,$M$4:$M$12,FALSE))/INDEX($Y$4:$Y$12,MATCH(R$17,$M$4:$M$12,FALSE)),2)} -> 5 | S18: {=ROUND(INDEX($N$4:$N$12,MATCH($M18,$M$4:$M$12,FALSE))/INDEX($Y$4:$Y$12,MATCH(S$17,$M$4:$M$12,FALSE)),2)} -> 5.45 | T18: {=ROUND(INDEX($N$4:$N$12,MATCH($M18,$M$4:$M$12,FALSE))/INDEX($Y$4:$Y$12,MATCH(T$17,$M$4:$M$12,FALSE)),2)} -> 4.8 | U18: {=ROUND(INDEX($N$4:$N$12,MATCH($M18,$M$4:$M$12,FALSE))/INDEX($Y$4:$Y$12,MATCH(U$17,$M$4:$M$12,FALSE)),2)} -> 5
B19: 坦克 | C19: {=属性分配!C$11*属性分配!C$4/$E$16*INDEX($C$4:$J$12,MATCH($B19,$B$4:$B$12,FALSE),MATCH(C$17,$C$3:$J$3,FALSE))} -> 12.15 | D19: {=属性分配!D$11*属性分配!D$4/$E$16*INDEX($C$4:$J$12,MATCH($B19,$B$4:$B$12,FALSE),MATCH(D$17,$C$3:$J$3,FALSE))} -> 1.2 | E19: {=属性分配!E$11*属性分配!E$4/$E$16*INDEX($C$4:$J$12,MATCH($B19,$B$4:$B$12,FALSE),MATCH(E$17,$C$3:$J$3,FALSE))} -> 1.125 | F19: {=属性分配!F$11*属性分配!F$4/$E$16*INDEX($C$4:$J$12,MATCH($B19,$B$4:$B$12,FALSE),MATCH(F$17,$C$3:$J$3,FALSE))} -> 1.2 | G19: {=属性分配!G$11*属性分配!G$4/$E$16*INDEX($C$4:$J$12,MATCH($B19,$B$4:$B$12,FALSE),MATCH(G$17,$C$3:$J$3,FALSE))} -> 0.8 | H19: {=属性分配!H$11*属性分配!H$4/$E$16*INDEX($C$4:$J$12,MATCH($B19,$B$4:$B$12,FALSE),MATCH(H$17,$C$3:$J$3,FALSE))} -> 0.6 | I19: {=属性分配!I$11*属性分配!I$4/$E$16*INDEX($C$4:$J$12,MATCH($B19,$B$4:$B$12,FALSE),MATCH(I$17,$C$3:$J$3,FALSE))} -> 0.6 | J19: {=属性分配!J$11*属性分配!J$4/$E$16*INDEX($C$4:$J$12,MATCH($B19,$B$4:$B$12,FALSE),MATCH(J$17,$C$3:$J$3,FALSE))} -> 0.6 | K19: {=SUMPRODUCT($C19:$G19,$C$14:$G$14)} -> 19.375 | M19: 坦克 | N19: {=ROUND(INDEX($N$4:$N$12,MATCH($M19,$M$4:$M$12,FALSE))/INDEX($Y$4:$Y$12,MATCH(N$17,$M$4:$M$12,FALSE)),2)} -> 8.1 | O19: {=ROUND(INDEX($N$4:$N$12,MATCH($M19,$M$4:$M$12,FALSE))/INDEX($Y$4:$Y$12,MATCH(O$17,$M$4:$M$12,FALSE)),2)} -> 10.13 | P19: {=ROUND(INDEX($N$4:$N$12,MATCH($M19,$M$4:$M$12,FALSE))/INDEX($Y$4:$Y$12,MATCH(P$17,$M$4:$M$12,FALSE)),2)} -> 7.36 | Q19: {=ROUND(INDEX($N$4:$N$12,MATCH($M19,$M$4:$M$12,FALSE))/INDEX($Y$4:$Y$12,MATCH(Q$17,$M$4:$M$12,FALSE)),2)} -> 10.13 | R19: {=ROUND(INDEX($N$4:$N$12,MATCH($M19,$M$4:$M$12,FALSE))/INDEX($Y$4:$Y$12,MATCH(R$17,$M$4:$M$12,FALSE)),2)} -> 6.75 | S19: {=ROUND(INDEX($N$4:$N$12,MATCH($M19,$M$4:$M$12,FALSE))/INDEX($Y$4:$Y$12,MATCH(S$17,$M$4:$M$12,FALSE)),2)} -> 7.36 | T19: {=ROUND(INDEX($N$4:$N$12,MATCH($M19,$M$4:$M$12,FALSE))/INDEX($Y$4:$Y$12,MATCH(T$17,$M$4:$M$12,FALSE)),2)} -> 6.48 | U19: {=ROUND(INDEX($N$4:$N$12,MATCH($M19,$M$4:$M$12,FALSE))/INDEX($Y$4:$Y$12,MATCH(U$17,$M$4:$M$12,FALSE)),2)} -> 6.75
B20: 战士 | C20: {=属性分配!C$11*属性分配!C$4/$E$16*INDEX($C$4:$J$12,MATCH($B20,$B$4:$B$12,FALSE),MATCH(C$17,$C$3:$J$3,FALSE))} -> 9.45 | D20: {=属性分配!D$11*属性分配!D$4/$E$16*INDEX($C$4:$J$12,MATCH($B20,$B$4:$B$12,FALSE),MATCH(D$17,$C$3:$J$3,FALSE))} -> 1.65 | E20: {=属性分配!E$11*属性分配!E$4/$E$16*INDEX($C$4:$J$12,MATCH($B20,$B$4:$B$12,FALSE),MATCH(E$17,$C$3:$J$3,FALSE))} -> 1.2 | F20: {=属性分配!F$11*属性分配!F$4/$E$16*INDEX($C$4:$J$12,MATCH($B20,$B$4:$B$12,FALSE),MATCH(F$17,$C$3:$J$3,FALSE))} -> 1 | G20: {=属性分配!G$11*属性分配!G$4/$E$16*INDEX($C$4:$J$12,MATCH($B20,$B$4:$B$12,FALSE),MATCH(G$17,$C$3:$J$3,FALSE))} -> 0.95 | H20: {=属性分配!H$11*属性分配!H$4/$E$16*INDEX($C$4:$J$12,MATCH($B20,$B$4:$B$12,FALSE),MATCH(H$17,$C$3:$J$3,FALSE))} -> 0.7 | I20: {=属性分配!I$11*属性分配!I$4/$E$16*INDEX($C$4:$J$12,MATCH($B20,$B$4:$B$12,FALSE),MATCH(I$17,$C$3:$J$3,FALSE))} -> 0.5 | J20: {=属性分配!J$11*属性分配!J$4/$E$16*INDEX($C$4:$J$12,MATCH($B20,$B$4:$B$12,FALSE),MATCH(J$17,$C$3:$J$3,FALSE))} -> 0.6 | K20: {=SUMPRODUCT($C20:$G20,$C$14:$G$14)} -> 20.025 | M20: 战士 | N20: {=ROUND(INDEX($N$4:$N$12,MATCH($M20,$M$4:$M$12,FALSE))/INDEX($Y$4:$Y$12,MATCH(N$17,$M$4:$M$12,FALSE)),2)} -> 6.3 | O20: {=ROUND(INDEX($N$4:$N$12,MATCH($M20,$M$4:$M$12,FALSE))/INDEX($Y$4:$Y$12,MATCH(O$17,$M$4:$M$12,FALSE)),2)} -> 7.88 | P20: {=ROUND(INDEX($N$4:$N$12,MATCH($M20,$M$4:$M$12,FALSE))/INDEX($Y$4:$Y$12,MATCH(P$17,$M$4:$M$12,FALSE)),2)} -> 5.73 | Q20: {=ROUND(INDEX($N$4:$N$12,MATCH($M20,$M$4:$M$12,FALSE))/INDEX($Y$4:$Y$12,MATCH(Q$17,$M$4:$M$12,FALSE)),2)} -> 7.88 | R20: {=ROUND(INDEX($N$4:$N$12,MATCH($M20,$M$4:$M$12,FALSE))/INDEX($Y$4:$Y$12,MATCH(R$17,$M$4:$M$12,FALSE)),2)} -> 5.25 | S20: {=ROUND(INDEX($N$4:$N$12,MATCH($M20,$M$4:$M$12,FALSE))/INDEX($Y$4:$Y$12,MATCH(S$17,$M$4:$M$12,FALSE)),2)} -> 5.73 | T20: {=ROUND(INDEX($N$4:$N$12,MATCH($M20,$M$4:$M$12,FALSE))/INDEX($Y$4:$Y$12,MATCH(T$17,$M$4:$M$12,FALSE)),2)} -> 5.04 | U20: {=ROUND(INDEX($N$4:$N$12,MATCH($M20,$M$4:$M$12,FALSE))/INDEX($Y$4:$Y$12,MATCH(U$17,$M$4:$M$12,FALSE)),2)} -> 5.25
B21: 法坦 | C21: {=属性分配!C$11*属性分配!C$4/$E$16*INDEX($C$4:$J$12,MATCH($B21,$B$4:$B$12,FALSE),MATCH(C$17,$C$3:$J$3,FALSE))} -> 11.7 | D21: {=属性分配!D$11*属性分配!D$4/$E$16*INDEX($C$4:$J$12,MATCH($B21,$B$4:$B$12,FALSE),MATCH(D$17,$C$3:$J$3,FALSE))} -> 1.125 | E21: {=属性分配!E$11*属性分配!E$4/$E$16*INDEX($C$4:$J$12,MATCH($B21,$B$4:$B$12,FALSE),MATCH(E$17,$C$3:$J$3,FALSE))} -> 1.2 | F21: {=属性分配!F$11*属性分配!F$4/$E$16*INDEX($C$4:$J$12,MATCH($B21,$B$4:$B$12,FALSE),MATCH(F$17,$C$3:$J$3,FALSE))} -> 0.95 | G21: {=属性分配!G$11*属性分配!G$4/$E$16*INDEX($C$4:$J$12,MATCH($B21,$B$4:$B$12,FALSE),MATCH(G$17,$C$3:$J$3,FALSE))} -> 1.2 | H21: {=属性分配!H$11*属性分配!H$4/$E$16*INDEX($C$4:$J$12,MATCH($B21,$B$4:$B$12,FALSE),MATCH(H$17,$C$3:$J$3,FALSE))} -> 0.5 | I21: {=属性分配!I$11*属性分配!I$4/$E$16*INDEX($C$4:$J$12,MATCH($B21,$B$4:$B$12,FALSE),MATCH(I$17,$C$3:$J$3,FALSE))} -> 0.7 | J21: {=属性分配!J$11*属性分配!J$4/$E$16*INDEX($C$4:$J$12,MATCH($B21,$B$4:$B$12,FALSE),MATCH(J$17,$C$3:$J$3,FALSE))} -> 0.6 | K21: {=SUMPRODUCT($C21:$G21,$C$14:$G$14)} -> 19.45 | M21: 法坦 | N21: {=ROUND(INDEX($N$4:$N$12,MATCH($M21,$M$4:$M$12,FALSE))/INDEX($Y$4:$Y$12,MATCH(N$17,$M$4:$M$12,FALSE)),2)} -> 7.8 | O21: {=ROUND(INDEX($N$4:$N$12,MATCH($M21,$M$4:$M$12,FALSE))/INDEX($Y$4:$Y$12,MATCH(O$17,$M$4:$M$12,FALSE)),2)} -> 9.75 | P21: {=ROUND(INDEX($N$4:$N$12,MATCH($M21,$M$4:$M$12,FALSE))/INDEX($Y$4:$Y$12,MATCH(P$17,$M$4:$M$12,FALSE)),2)} -> 7.09 | Q21: {=ROUND(INDEX($N$4:$N$12,MATCH($M21,$M$4:$M$12,FALSE))/INDEX($Y$4:$Y$12,MATCH(Q$17,$M$4:$M$12,FALSE)),2)} -> 9.75 | R21: {=ROUND(INDEX($N$4:$N$12,MATCH($M21,$M$4:$M$12,FALSE))/INDEX($Y$4:$Y$12,MATCH(R$17,$M$4:$M$12,FALSE)),2)} -> 6.5 | S21: {=ROUND(INDEX($N$4:$N$12,MATCH($M21,$M$4:$M$12,FALSE))/INDEX($Y$4:$Y$12,MATCH(S$17,$M$4:$M$12,FALSE)),2)} -> 7.09 | T21: {=ROUND(INDEX($N$4:$N$12,MATCH($M21,$M$4:$M$12,FALSE))/INDEX($Y$4:$Y$12,MATCH(T$17,$M$4:$M$12,FALSE)),2)} -> 6.24 | U21: {=ROUND(INDEX($N$4:$N$12,MATCH($M21,$M$4:$M$12,FALSE))/INDEX($Y$4:$Y$12,MATCH(U$17,$M$4:$M$12,FALSE)),2)} -> 6.5
B22: 刺客 | C22: {=属性分配!C$11*属性分配!C$4/$E$16*INDEX($C$4:$J$12,MATCH($B22,$B$4:$B$12,FALSE),MATCH(C$17,$C$3:$J$3,FALSE))} -> 8.1 | D22: {=属性分配!D$11*属性分配!D$4/$E$16*INDEX($C$4:$J$12,MATCH($B22,$B$4:$B$12,FALSE),MATCH(D$17,$C$3:$J$3,FALSE))} -> 1.8 | E22: {=属性分配!E$11*属性分配!E$4/$E$16*INDEX($C$4:$J$12,MATCH($B22,$B$4:$B$12,FALSE),MATCH(E$17,$C$3:$J$3,FALSE))} -> 1.35 | F22: {=属性分配!F$11*属性分配!F$4/$E$16*INDEX($C$4:$J$12,MATCH($B22,$B$4:$B$12,FALSE),MATCH(F$17,$C$3:$J$3,FALSE))} -> 0.9 | G22: {=属性分配!G$11*属性分配!G$4/$E$16*INDEX($C$4:$J$12,MATCH($B22,$B$4:$B$12,FALSE),MATCH(G$17,$C$3:$J$3,FALSE))} -> 0.9 | H22: {=属性分配!H$11*属性分配!H$4/$E$16*INDEX($C$4:$J$12,MATCH($B22,$B$4:$B$12,FALSE),MATCH(H$17,$C$3:$J$3,FALSE))} -> 0.5 | I22: {=属性分配!I$11*属性分配!I$4/$E$16*INDEX($C$4:$J$12,MATCH($B22,$B$4:$B$12,FALSE),MATCH(I$17,$C$3:$J$3,FALSE))} -> 0.6 | J22: {=属性分配!J$11*属性分配!J$4/$E$16*INDEX($C$4:$J$12,MATCH($B22,$B$4:$B$12,FALSE),MATCH(J$17,$C$3:$J$3,FALSE))} -> 0.7 | K22: {=SUMPRODUCT($C22:$G22,$C$14:$G$14)} -> 20.25 | M22: 刺客 | N22: {=ROUND(INDEX($N$4:$N$12,MATCH($M22,$M$4:$M$12,FALSE))/INDEX($Y$4:$Y$12,MATCH(N$17,$M$4:$M$12,FALSE)),2)} -> 5.4 | O22: {=ROUND(INDEX($N$4:$N$12,MATCH($M22,$M$4:$M$12,FALSE))/INDEX($Y$4:$Y$12,MATCH(O$17,$M$4:$M$12,FALSE)),2)} -> 6.75 | P22: {=ROUND(INDEX($N$4:$N$12,MATCH($M22,$M$4:$M$12,FALSE))/INDEX($Y$4:$Y$12,MATCH(P$17,$M$4:$M$12,FALSE)),2)} -> 4.91 | Q22: {=ROUND(INDEX($N$4:$N$12,MATCH($M22,$M$4:$M$12,FALSE))/INDEX($Y$4:$Y$12,MATCH(Q$17,$M$4:$M$12,FALSE)),2)} -> 6.75 | R22: {=ROUND(INDEX($N$4:$N$12,MATCH($M22,$M$4:$M$12,FALSE))/INDEX($Y$4:$Y$12,MATCH(R$17,$M$4:$M$12,FALSE)),2)} -> 4.5 | S22: {=ROUND(INDEX($N$4:$N$12,MATCH($M22,$M$4:$M$12,FALSE))/INDEX($Y$4:$Y$12,MATCH(S$17,$M$4:$M$12,FALSE)),2)} -> 4.91 | T22: {=ROUND(INDEX($N$4:$N$12,MATCH($M22,$M$4:$M$12,FALSE))/INDEX($Y$4:$Y$12,MATCH(T$17,$M$4:$M$12,FALSE)),2)} -> 4.32 | U22: {=ROUND(INDEX($N$4:$N$12,MATCH($M22,$M$4:$M$12,FALSE))/INDEX($Y$4:$Y$12,MATCH(U$17,$M$4:$M$12,FALSE)),2)} -> 4.5
B23: 魔剑士 | C23: {=属性分配!C$11*属性分配!C$4/$E$16*INDEX($C$4:$J$12,MATCH($B23,$B$4:$B$12,FALSE),MATCH(C$17,$C$3:$J$3,FALSE))} -> 9 | D23: {=属性分配!D$11*属性分配!D$4/$E$16*INDEX($C$4:$J$12,MATCH($B23,$B$4:$B$12,FALSE),MATCH(D$17,$C$3:$J$3,FALSE))} -> 1.35 | E23: {=属性分配!E$11*属性分配!E$4/$E$16*INDEX($C$4:$J$12,MATCH($B23,$B$4:$B$12,FALSE),MATCH(E$17,$C$3:$J$3,FALSE))} -> 1.65 | F23: {=属性分配!F$11*属性分配!F$4/$E$16*INDEX($C$4:$J$12,MATCH($B23,$B$4:$B$12,FALSE),MATCH(F$17,$C$3:$J$3,FALSE))} -> 0.9 | G23: {=属性分配!G$11*属性分配!G$4/$E$16*INDEX($C$4:$J$12,MATCH($B23,$B$4:$B$12,FALSE),MATCH(G$17,$C$3:$J$3,FALSE))} -> 0.9 | H23: {=属性分配!H$11*属性分配!H$4/$E$16*INDEX($C$4:$J$12,MATCH($B23,$B$4:$B$12,FALSE),MATCH(H$17,$C$3:$J$3,FALSE))} -> 0.6 | I23: {=属性分配!I$11*属性分配!I$4/$E$16*INDEX($C$4:$J$12,MATCH($B23,$B$4:$B$12,FALSE),MATCH(I$17,$C$3:$J$3,FALSE))} -> 0.7 | J23: {=属性分配!J$11*属性分配!J$4/$E$16*INDEX($C$4:$J$12,MATCH($B23,$B$4:$B$12,FALSE),MATCH(J$17,$C$3:$J$3,FALSE))} -> 0.5 | K23: {=SUMPRODUCT($C23:$G23,$C$14:$G$14)} -> 20.1 | M23: 魔剑士 | N23: {=ROUND(INDEX($N$4:$N$12,MATCH($M23,$M$4:$M$12,FALSE))/INDEX($Y$4:$Y$12,MATCH(N$17,$M$4:$M$12,FALSE)),2)} -> 6 | O23: {=ROUND(INDEX($N$4:$N$12,MATCH($M23,$M$4:$M$12,FALSE))/INDEX($Y$4:$Y$12,MATCH(O$17,$M$4:$M$12,FALSE)),2)} -> 7.5 | P23: {=ROUND(INDEX($N$4:$N$12,MATCH($M23,$M$4:$M$12,FALSE))/INDEX($Y$4:$Y$12,MATCH(P$17,$M$4:$M$12,FALSE)),2)} -> 5.45 | Q23: {=ROUND(INDEX($N$4:$N$12,MATCH($M23,$M$4:$M$12,FALSE))/INDEX($Y$4:$Y$12,MATCH(Q$17,$M$4:$M$12,FALSE)),2)} -> 7.5 | R23: {=ROUND(INDEX($N$4:$N$12,MATCH($M23,$M$4:$M$12,FALSE))/INDEX($Y$4:$Y$12,MATCH(R$17,$M$4:$M$12,FALSE)),2)} -> 5 | S23: {=ROUND(INDEX($N$4:$N$12,MATCH($M23,$M$4:$M$12,FALSE))/INDEX($Y$4:$Y$12,MATCH(S$17,$M$4:$M$12,FALSE)),2)} -> 5.45 | T23: {=ROUND(INDEX($N$4:$N$12,MATCH($M23,$M$4:$M$12,FALSE))/INDEX($Y$4:$Y$12,MATCH(T$17,$M$4:$M$12,FALSE)),2)} -> 4.8 | U23: {=ROUND(INDEX($N$4:$N$12,MATCH($M23,$M$4:$M$12,FALSE))/INDEX($Y$4:$Y$12,MATCH(U$17,$M$4:$M$12,FALSE)),2)} -> 5
B24: 法师 | C24: {=属性分配!C$11*属性分配!C$4/$E$16*INDEX($C$4:$J$12,MATCH($B24,$B$4:$B$12,FALSE),MATCH(C$17,$C$3:$J$3,FALSE))} -> 8.1 | D24: {=属性分配!D$11*属性分配!D$4/$E$16*INDEX($C$4:$J$12,MATCH($B24,$B$4:$B$12,FALSE),MATCH(D$17,$C$3:$J$3,FALSE))} -> 1.275 | E24: {=属性分配!E$11*属性分配!E$4/$E$16*INDEX($C$4:$J$12,MATCH($B24,$B$4:$B$12,FALSE),MATCH(E$17,$C$3:$J$3,FALSE))} -> 1.875 | F24: {=属性分配!F$11*属性分配!F$4/$E$16*INDEX($C$4:$J$12,MATCH($B24,$B$4:$B$12,FALSE),MATCH(F$17,$C$3:$J$3,FALSE))} -> 0.75 | G24: {=属性分配!G$11*属性分配!G$4/$E$16*INDEX($C$4:$J$12,MATCH($B24,$B$4:$B$12,FALSE),MATCH(G$17,$C$3:$J$3,FALSE))} -> 1.05 | H24: {=属性分配!H$11*属性分配!H$4/$E$16*INDEX($C$4:$J$12,MATCH($B24,$B$4:$B$12,FALSE),MATCH(H$17,$C$3:$J$3,FALSE))} -> 0.5 | I24: {=属性分配!I$11*属性分配!I$4/$E$16*INDEX($C$4:$J$12,MATCH($B24,$B$4:$B$12,FALSE),MATCH(I$17,$C$3:$J$3,FALSE))} -> 0.8 | J24: {=属性分配!J$11*属性分配!J$4/$E$16*INDEX($C$4:$J$12,MATCH($B24,$B$4:$B$12,FALSE),MATCH(J$17,$C$3:$J$3,FALSE))} -> 0.5 | K24: {=SUMPRODUCT($C24:$G24,$C$14:$G$14)} -> 20.25 | M24: 法师 | N24: {=ROUND(INDEX($N$4:$N$12,MATCH($M24,$M$4:$M$12,FALSE))/INDEX($Y$4:$Y$12,MATCH(N$17,$M$4:$M$12,FALSE)),2)} -> 5.4 | O24: {=ROUND(INDEX($N$4:$N$12,MATCH($M24,$M$4:$M$12,FALSE))/INDEX($Y$4:$Y$12,MATCH(O$17,$M$4:$M$12,FALSE)),2)} -> 6.75 | P24: {=ROUND(INDEX($N$4:$N$12,MATCH($M24,$M$4:$M$12,FALSE))/INDEX($Y$4:$Y$12,MATCH(P$17,$M$4:$M$12,FALSE)),2)} -> 4.91 | Q24: {=ROUND(INDEX($N$4:$N$12,MATCH($M24,$M$4:$M$12,FALSE))/INDEX($Y$4:$Y$12,MATCH(Q$17,$M$4:$M$12,FALSE)),2)} -> 6.75 | R24: {=ROUND(INDEX($N$4:$N$12,MATCH($M24,$M$4:$M$12,FALSE))/INDEX($Y$4:$Y$12,MATCH(R$17,$M$4:$M$12,FALSE)),2)} -> 4.5 | S24: {=ROUND(INDEX($N$4:$N$12,MATCH($M24,$M$4:$M$12,FALSE))/INDEX($Y$4:$Y$12,MATCH(S$17,$M$4:$M$12,FALSE)),2)} -> 4.91 | T24: {=ROUND(INDEX($N$4:$N$12,MATCH($M24,$M$4:$M$12,FALSE))/INDEX($Y$4:$Y$12,MATCH(T$17,$M$4:$M$12,FALSE)),2)} -> 4.32 | U24: {=ROUND(INDEX($N$4:$N$12,MATCH($M24,$M$4:$M$12,FALSE))/INDEX($Y$4:$Y$12,MATCH(U$17,$M$4:$M$12,FALSE)),2)} -> 4.5
B25: 猎人 | C25: {=属性分配!C$11*属性分配!C$4/$E$16*INDEX($C$4:$J$12,MATCH($B25,$B$4:$B$12,FALSE),MATCH(C$17,$C$3:$J$3,FALSE))} -> 8.55 | D25: {=属性分配!D$11*属性分配!D$4/$E$16*INDEX($C$4:$J$12,MATCH($B25,$B$4:$B$12,FALSE),MATCH(D$17,$C$3:$J$3,FALSE))} -> 1.8 | E25: {=属性分配!E$11*属性分配!E$4/$E$16*INDEX($C$4:$J$12,MATCH($B25,$B$4:$B$12,FALSE),MATCH(E$17,$C$3:$J$3,FALSE))} -> 1.2 | F25: {=属性分配!F$11*属性分配!F$4/$E$16*INDEX($C$4:$J$12,MATCH($B25,$B$4:$B$12,FALSE),MATCH(F$17,$C$3:$J$3,FALSE))} -> 0.95 | G25: {=属性分配!G$11*属性分配!G$4/$E$16*INDEX($C$4:$J$12,MATCH($B25,$B$4:$B$12,FALSE),MATCH(G$17,$C$3:$J$3,FALSE))} -> 0.9 | H25: {=属性分配!H$11*属性分配!H$4/$E$16*INDEX($C$4:$J$12,MATCH($B25,$B$4:$B$12,FALSE),MATCH(H$17,$C$3:$J$3,FALSE))} -> 0.7 | I25: {=属性分配!I$11*属性分配!I$4/$E$16*INDEX($C$4:$J$12,MATCH($B25,$B$4:$B$12,FALSE),MATCH(I$17,$C$3:$J$3,FALSE))} -> 0.5 | J25: {=属性分配!J$11*属性分配!J$4/$E$16*INDEX($C$4:$J$12,MATCH($B25,$B$4:$B$12,FALSE),MATCH(J$17,$C$3:$J$3,FALSE))} -> 0.6 | K25: {=SUMPRODUCT($C25:$G25,$C$14:$G$14)} -> 19.975 | M25: 猎人 | N25: {=ROUND(INDEX($N$4:$N$12,MATCH($M25,$M$4:$M$12,FALSE))/INDEX($Y$4:$Y$12,MATCH(N$17,$M$4:$M$12,FALSE)),2)} -> 5.7 | O25: {=ROUND(INDEX($N$4:$N$12,MATCH($M25,$M$4:$M$12,FALSE))/INDEX($Y$4:$Y$12,MATCH(O$17,$M$4:$M$12,FALSE)),2)} -> 7.13 | P25: {=ROUND(INDEX($N$4:$N$12,MATCH($M25,$M$4:$M$12,FALSE))/INDEX($Y$4:$Y$12,MATCH(P$17,$M$4:$M$12,FALSE)),2)} -> 5.18 | Q25: {=ROUND(INDEX($N$4:$N$12,MATCH($M25,$M$4:$M$12,FALSE))/INDEX($Y$4:$Y$12,MATCH(Q$17,$M$4:$M$12,FALSE)),2)} -> 7.13 | R25: {=ROUND(INDEX($N$4:$N$12,MATCH($M25,$M$4:$M$12,FALSE))/INDEX($Y$4:$Y$12,MATCH(R$17,$M$4:$M$12,FALSE)),2)} -> 4.75 | S25: {=ROUND(INDEX($N$4:$N$12,MATCH($M25,$M$4:$M$12,FALSE))/INDEX($Y$4:$Y$12,MATCH(S$17,$M$4:$M$12,FALSE)),2)} -> 5.18 | T25: {=ROUND(INDEX($N$4:$N$12,MATCH($M25,$M$4:$M$12,FALSE))/INDEX($Y$4:$Y$12,MATCH(T$17,$M$4:$M$12,FALSE)),2)} -> 4.56 | U25: {=ROUND(INDEX($N$4:$N$12,MATCH($M25,$M$4:$M$12,FALSE))/INDEX($Y$4:$Y$12,MATCH(U$17,$M$4:$M$12,FALSE)),2)} -> 4.75
B27: 卡牌升星 BasePct
B28: 星级 | C28: 生命值 | D28: 外攻 | E28: 内攻 | F28: 外防 | G28: 内防 | H28: 农牧 | I28: 学识 | J28: 手工 | M28: 升星消耗 | N28: 资源来源 | T28: 突破级数和突破辅助队列
B29: 0 | C29: {=INDEX(属性分配!$C$13:$J$13,MATCH(C$28,属性分配!$C$3:$J$3,FALSE))/(属性分配!C$11+1)*$B29/$B$34} -> 0 | D29: {=INDEX(属性分配!$C$13:$J$13,MATCH(D$28,属性分配!$C$3:$J$3,FALSE))/(属性分配!D$11+1)*$B29/$B$34} -> 0 | E29: {=INDEX(属性分配!$C$13:$J$13,MATCH(E$28,属性分配!$C$3:$J$3,FALSE))/(属性分配!E$11+1)*$B29/$B$34} -> 0 | F29: {=INDEX(属性分配!$C$13:$J$13,MATCH(F$28,属性分配!$C$3:$J$3,FALSE))/(属性分配!F$11+1)*$B29/$B$34} -> 0 | G29: {=INDEX(属性分配!$C$13:$J$13,MATCH(G$28,属性分配!$C$3:$J$3,FALSE))/(属性分配!G$11+1)*$B29/$B$34} -> 0 | H29: {=INDEX(属性分配!$C$13:$J$13,MATCH(H$28,属性分配!$C$3:$J$3,FALSE))/(属性分配!H$11+1)*$B29/$B$34} -> 0 | I29: {=INDEX(属性分配!$C$13:$J$13,MATCH(I$28,属性分配!$C$3:$J$3,FALSE))/(属性分配!I$11+1)*$B29/$B$34} -> 0 | J29: {=INDEX(属性分配!$C$13:$J$13,MATCH(J$28,属性分配!$C$3:$J$3,FALSE))/(属性分配!J$11+1)*$B29/$B$34} -> 0 | M29: 1 | N29: 抽卡 | T29: 突破等级 | U29: 原突破属性比 | V29: 调整后属性比 | X29: 单项属性单项增加 | Y29: 小节点整体属性比
B30: 1 | C30: {=INDEX(属性分配!$C$13:$J$13,MATCH(C$28,属性分配!$C$3:$J$3,FALSE))/(属性分配!C$11+属性分配!C$12+1)*$B30/$B$34} -> 0.4 | D30: {=INDEX(属性分配!$C$13:$J$13,MATCH(D$28,属性分配!$C$3:$J$3,FALSE))/(属性分配!D$11+属性分配!D$12+1)*$B30/$B$34} -> 0.2 | E30: {=INDEX(属性分配!$C$13:$J$13,MATCH(E$28,属性分配!$C$3:$J$3,FALSE))/(属性分配!E$11+属性分配!E$12+1)*$B30/$B$34} -> 0.2 | F30: {=INDEX(属性分配!$C$13:$J$13,MATCH(F$28,属性分配!$C$3:$J$3,FALSE))/(属性分配!F$11+属性分配!F$12+1)*$B30/$B$34} -> 0.2 | G30: {=INDEX(属性分配!$C$13:$J$13,MATCH(G$28,属性分配!$C$3:$J$3,FALSE))/(属性分配!G$11+属性分配!G$12+1)*$B30/$B$34} -> 0.2 | H30: {=INDEX(属性分配!$C$13:$J$13,MATCH(H$28,属性分配!$C$3:$J$3,FALSE))/(属性分配!H$11+属性分配!H$12+1)*$B30/$B$34} -> 0.15 | I30: {=INDEX(属性分配!$C$13:$J$13,MATCH(I$28,属性分配!$C$3:$J$3,FALSE))/(属性分配!I$11+属性分配!I$12+1)*$B30/$B$34} -> 0.15 | J30: {=INDEX(属性分配!$C$13:$J$13,MATCH(J$28,属性分配!$C$3:$J$3,FALSE))/(属性分配!J$11+属性分配!J$12+1)*$B30/$B$34} -> 0.15 | M30: 1 | T30: 0 | U30: 0 | V30: 0
B31: 2 | C31: {=INDEX(属性分配!$C$13:$J$13,MATCH(C$28,属性分配!$C$3:$J$3,FALSE))/(属性分配!C$11+属性分配!C$12+1)*$B31/$B$34} -> 0.8 | D31: {=INDEX(属性分配!$C$13:$J$13,MATCH(D$28,属性分配!$C$3:$J$3,FALSE))/(属性分配!D$11+属性分配!D$12+1)*$B31/$B$34} -> 0.4 | E31: {=INDEX(属性分配!$C$13:$J$13,MATCH(E$28,属性分配!$C$3:$J$3,FALSE))/(属性分配!E$11+属性分配!E$12+1)*$B31/$B$34} -> 0.4 | F31: {=INDEX(属性分配!$C$13:$J$13,MATCH(F$28,属性分配!$C$3:$J$3,FALSE))/(属性分配!F$11+属性分配!F$12+1)*$B31/$B$34} -> 0.4 | G31: {=INDEX(属性分配!$C$13:$J$13,MATCH(G$28,属性分配!$C$3:$J$3,FALSE))/(属性分配!G$11+属性分配!G$12+1)*$B31/$B$34} -> 0.4 | H31: {=INDEX(属性分配!$C$13:$J$13,MATCH(H$28,属性分配!$C$3:$J$3,FALSE))/(属性分配!H$11+属性分配!H$12+1)*$B31/$B$34} -> 0.3 | I31: {=INDEX(属性分配!$C$13:$J$13,MATCH(I$28,属性分配!$C$3:$J$3,FALSE))/(属性分配!I$11+属性分配!I$12+1)*$B31/$B$34} -> 0.3 | J31: {=INDEX(属性分配!$C$13:$J$13,MATCH(J$28,属性分配!$C$3:$J$3,FALSE))/(属性分配!J$11+属性分配!J$12+1)*$B31/$B$34} -> 0.3 | M31: 1 | T31: 1 | U31: 0.05 | V31: 0.025
B32: 3 | C32: {=INDEX(属性分配!$C$13:$J$13,MATCH(C$28,属性分配!$C$3:$J$3,FALSE))/(属性分配!C$11+属性分配!C$12+1)*$B32/$B$34} -> 1.2 | D32: {=INDEX(属性分配!$C$13:$J$13,MATCH(D$28,属性分配!$C$3:$J$3,FALSE))/(属性分配!D$11+属性分配!D$12+1)*$B32/$B$34} -> 0.6 | E32: {=INDEX(属性分配!$C$13:$J$13,MATCH(E$28,属性分配!$C$3:$J$3,FALSE))/(属性分配!E$11+属性分配!E$12+1)*$B32/$B$34} -> 0.6 | F32: {=INDEX(属性分配!$C$13:$J$13,MATCH(F$28,属性分配!$C$3:$J$3,FALSE))/(属性分配!F$11+属性分配!F$12+1)*$B32/$B$34} -> 0.6 | G32: {=INDEX(属性分配!$C$13:$J$13,MATCH(G$28,属性分配!$C$3:$J$3,FALSE))/(属性分配!G$11+属性分配!G$12+1)*$B32/$B$34} -> 0.6 | H32: {=INDEX(属性分配!$C$13:$J$13,MATCH(H$28,属性分配!$C$3:$J$3,FALSE))/(属性分配!H$11+属性分配!H$12+1)*$B32/$B$34} -> 0.45 | I32: {=INDEX(属性分配!$C$13:$J$13,MATCH(I$28,属性分配!$C$3:$J$3,FALSE))/(属性分配!I$11+属性分配!I$12+1)*$B32/$B$34} -> 0.45 | J32: {=INDEX(属性分配!$C$13:$J$13,MATCH(J$28,属性分配!$C$3:$J$3,FALSE))/(属性分配!J$11+属性分配!J$12+1)*$B32/$B$34} -> 0.45 | M32: 1 | T32: 2 | U32: 0.1 | V32: 0.05
B33: 4 | C33: {=INDEX(属性分配!$C$13:$J$13,MATCH(C$28,属性分配!$C$3:$J$3,FALSE))/(属性分配!C$11+属性分配!C$12+1)*$B33/$B$34} -> 1.6 | D33: {=INDEX(属性分配!$C$13:$J$13,MATCH(D$28,属性分配!$C$3:$J$3,FALSE))/(属性分配!D$11+属性分配!D$12+1)*$B33/$B$34} -> 0.8 | E33: {=INDEX(属性分配!$C$13:$J$13,MATCH(E$28,属性分配!$C$3:$J$3,FALSE))/(属性分配!E$11+属性分配!E$12+1)*$B33/$B$34} -> 0.8 | F33: {=INDEX(属性分配!$C$13:$J$13,MATCH(F$28,属性分配!$C$3:$J$3,FALSE))/(属性分配!F$11+属性分配!F$12+1)*$B33/$B$34} -> 0.8 | G33: {=INDEX(属性分配!$C$13:$J$13,MATCH(G$28,属性分配!$C$3:$J$3,FALSE))/(属性分配!G$11+属性分配!G$12+1)*$B33/$B$34} -> 0.8 | H33: {=INDEX(属性分配!$C$13:$J$13,MATCH(H$28,属性分配!$C$3:$J$3,FALSE))/(属性分配!H$11+属性分配!H$12+1)*$B33/$B$34} -> 0.6 | I33: {=INDEX(属性分配!$C$13:$J$13,MATCH(I$28,属性分配!$C$3:$J$3,FALSE))/(属性分配!I$11+属性分配!I$12+1)*$B33/$B$34} -> 0.6 | J33: {=INDEX(属性分配!$C$13:$J$13,MATCH(J$28,属性分配!$C$3:$J$3,FALSE))/(属性分配!J$11+属性分配!J$12+1)*$B33/$B$34} -> 0.6 | M33: 1 | T33: 3 | U33: 0.175 | V33: 0.075
B34: 5 | C34: {=INDEX(属性分配!$C$13:$J$13,MATCH(C$28,属性分配!$C$3:$J$3,FALSE))/(属性分配!C$11+属性分配!C$12+1)*$B34/$B$34} -> 2 | D34: {=INDEX(属性分配!$C$13:$J$13,MATCH(D$28,属性分配!$C$3:$J$3,FALSE))/(属性分配!D$11+属性分配!D$12+1)*$B34/$B$34} -> 1 | E34: {=INDEX(属性分配!$C$13:$J$13,MATCH(E$28,属性分配!$C$3:$J$3,FALSE))/(属性分配!E$11+属性分配!E$12+1)*$B34/$B$34} -> 1 | F34: {=INDEX(属性分配!$C$13:$J$13,MATCH(F$28,属性分配!$C$3:$J$3,FALSE))/(属性分配!F$11+属性分配!F$12+1)*$B34/$B$34} -> 1 | G34: {=INDEX(属性分配!$C$13:$J$13,MATCH(G$28,属性分配!$C$3:$J$3,FALSE))/(属性分配!G$11+属性分配!G$12+1)*$B34/$B$34} -> 1 | H34: {=INDEX(属性分配!$C$13:$J$13,MATCH(H$28,属性分配!$C$3:$J$3,FALSE))/(属性分配!H$11+属性分配!H$12+1)*$B34/$B$34} -> 0.75 | I34: {=INDEX(属性分配!$C$13:$J$13,MATCH(I$28,属性分配!$C$3:$J$3,FALSE))/(属性分配!I$11+属性分配!I$12+1)*$B34/$B$34} -> 0.75 | J34: {=INDEX(属性分配!$C$13:$J$13,MATCH(J$28,属性分配!$C$3:$J$3,FALSE))/(属性分配!J$11+属性分配!J$12+1)*$B34/$B$34} -> 0.75 | M34: 1 | T34: 4 | U34: 0.25 | V34: 0.1
B35: 备注：基础属性为1，升级提升比例为3，等于升星在1+3 =4的基础上提升了6 | P35: =0.02/20 -> 0.001 | T35: 5 | U35: 0.35 | V35: 0.13 | Y35: 0.1
B36: 使用BasePct增长，使升星不至于一下获得全部属性，而需要等级提升同步增长。另外升星可以拆为每星等比例，和突破有一定区分 | T36: 6 | U36: 0.45 | V36: 0.16
L37: 0.6 | M37: 0.4 | R37: =0.21/6 -> 0.035 | T37: 7 | U37: 0.575 | V37: 0.2
B38: 卡牌突破 BasePct | L38: 0.03 | M38: 20 | N38: 5 | T38: 8 | U38: 0.7 | V38: 0.25
A39: 等级需求 | B39: 突破层级 | C39: 生命值 | D39: 外攻 | E39: 内攻 | F39: 外防 | G39: 内防 | H39: 农牧 | I39: 学识 | J39: 手工 | K39: 属性占比 | L39: 单项加成比 | M39: 弟子实际投放 | N39: 换算实力模型比例 | O39: 消耗 | P39: 资源来源 | T39: 9 | U39: 0.85 | V39: 0.3
B40: 0 | C40: 0 | D40: 0 | E40: 0 | F40: 0 | G40: 0 | H40: 0 | I40: 0 | J40: 0 | K40: 0 | L40: 0 | N40: 0 | O40: 突破丹 | P40: 爬塔，副本通关 | T40: 10 | U40: 1 | V40: 0.35
A41: 6 | B41: 1 | C41: =C$60*$K41 -> 0.075 | D41: =D$60*$K41 -> 0.075 | E41: =E$60*$K41 -> 0.075 | F41: =F$60*$K41 -> 0.05 | G41: =G$60*$K41 -> 0.05 | H41: =H$60*$K41 -> 0 | I41: =I$60*$K41 -> 0 | J41: =J$60*$K41 -> 0 | K41: 0.025 | L41: =K41 -> 0.025 | N41: =L41/5 -> 0.005 | O41: 卡牌 | P41: 抽卡 | Q41: 0.025 | T41: 11 | V41: 0.4
A42: 12 | B42: 2 | C42: =C$60*$K42 -> 0.15 | D42: =D$60*$K42 -> 0.15 | E42: =E$60*$K42 -> 0.15 | F42: =F$60*$K42 -> 0.1 | G42: =G$60*$K42 -> 0.1 | H42: =H$60*$K42 -> 0 | I42: =I$60*$K42 -> 0 | J42: =J$60*$K42 -> 0 | K42: 0.05 | L42: =K42-K41 -> 0.025 | N42: =L42/$N$38+N41 -> 0.01 | Q42: 0.05 | T42: 12 | V42: 0.45
A43: 18 | B43: 3 | C43: =C$60*$K43 -> 0.225 | D43: =D$60*$K43 -> 0.225 | E43: =E$60*$K43 -> 0.225 | F43: =F$60*$K43 -> 0.15 | G43: =G$60*$K43 -> 0.15 | H43: =H$60*$K43 -> 0 | I43: =I$60*$K43 -> 0 | J43: =J$60*$K43 -> 0 | K43: 0.075 | L43: =K43-K42 -> 0.025 | N43: =L43/$N$38+N42 -> 0.015 | Q43: 0.075 | T43: 13 | V43: 0.51
A44: 24 | B44: 4 | C44: =C$60*$K44 -> 0.3 | D44: =D$60*$K44 -> 0.3 | E44: =E$60*$K44 -> 0.3 | F44: =F$60*$K44 -> 0.2 | G44: =G$60*$K44 -> 0.2 | H44: =H$60*$K44 -> 0 | I44: =I$60*$K44 -> 0 | J44: =J$60*$K44 -> 0 | K44: 0.1 | L44: =K44-K43 -> 0.025 | N44: =L44/$N$38+N43 -> 0.02 | Q44: 0.1 | T44: 14 | V44: 0.57
...

Sheet 弟子属性表
B1: 基础设定 | N1: 基础属性修正 - 调整弟子个体差异 | V1: 基础属性-1级，最终计算结果客户端显示取整 | AF1: 二级属性 | AX1: #基础属性Base-0级（标准属性*模板修正*品质强度修正*弟子个人修正） | BF1: #成长属性BaseAdd | BN1: #满级属性-当前配置 | BW1: #满级属性-满强化，满星级
V2: hp | W2: atk | X2: mp | Y2: ac | Z2: mc | AD2: asp | AE2: spd | AF2: hit | AG2: mis | AH2: cr | AI2: dcr | AJ2: crr | AL2: ad | AM2: rd | AP2: acp | AQ2: mcp
A3: 弟子id | B3: 弟子名称 | C3: 弟子职业 | D3: 品质 | E3: 资质强度 | F3: 品质强度修正 | G3: 最大突破级别 | H3: 最大星级 | I3: 是否显示投放 | J3: 初始等级 | K3: 初始星级 | L3: 初始突破等级 | M3: 初始经验 | N3: 生命值修正 | O3: 外攻修正 | P3: 内攻修正 | Q3: 外防修正 | R3: 内防修正 | S3: 农牧 | T3: 学识 | U3: 手工 | V3: 生命值 | W3: 外攻 | X3: 内攻 | Y3: 外防 | Z3: 内防 | AA3: 农牧 | AB3: 手工 | AC3: 学识 | AD3: 普攻速度 | AE3: 移动速度 | AF3: 命中率 | AG3: 闪避率 | AH3: 暴击率 | AI3: 抗暴率 | AJ3: 爆伤 | AK3: 暴击减伤 | AL3: 增伤率 | AM3: 减伤率 | AN3: 增伤值 | AO3: 减伤值 | AP3: 护甲穿透率 | AQ3: 法术穿透率 | AR3: 护甲穿透值 | AS3: 法术穿透值 | AT3: 吸血 | AU3: 治疗率 | AV3: 受治疗率 | AW3: 极速 | AX3: 生命值 | AY3: 外攻 | AZ3: 内攻 | BA3: 外防 | BB3: 内防 | BC3: 农牧 | BD3: 学识 | BE3: 手工 | BF3: 生命值 | BG3: 外攻 | BH3: 内攻 | BI3: 外防 | BJ3: 内防 | BK3: 农牧 | BL3: 学识 | BM3: 手工 | BN3: 生命值 | BO3: 外攻 | BP3: 内攻 | BQ3: 外防 | BR3: 内防 | BS3: 农牧 | BT3: 学识 | BU3: 手工 | BV3: 纯战斗力 | BW3: 生命值 | BX3: 外攻 | BY3: 内攻 | BZ3: 外防 | CA3: 内防 | CB3: 农牧 | CC3: 学识 | CD3: 手工 | CE3: 纯战斗力
A4: 10000 | B4: 模板1 | C4: 坦克 | D4: 4 | E4: 4 | F4: 1 | G4: 20 | H4: 5 | I4: 0 | J4: 1 | K4: 0 | L4: 0 | M4: 0 | N4: 1 | O4: 1 | P4: 1 | Q4: 1 | R4: 1 | S4: 1 | T4: 1 | U4: 1 | V4: {=ROUND((AX4+BF4*$J4+INDEX(职业模板!$C$40:$J$60,MATCH($L4,职业模板!$B$40:$B$60,FALSE),MATCH(V$3,职业模板!$C$39:$J$39,FALSE))*AX4)*(1+INDEX(职业模板!$C$29:$J$34,MATCH($K4,职业模板!$B$29:$B$34,FALSE),MATCH(V$3,职业模板!$C$28:$J$28,FALSE))),2)} -> 417.15 | W4: {=ROUND((AY4+BG4*$J4+INDEX(职业模板!$C$40:$J$60,MATCH($L4,职业模板!$B$40:$B$60,FALSE),MATCH(W$3,职业模板!$C$39:$J$39,FALSE))*AY4)*(1+INDEX(职业模板!$C$29:$J$34,MATCH($K4,职业模板!$B$29:$B$34,FALSE),MATCH(W$3,职业模板!$C$28:$J$28,FALSE))),2)} -> 41.2 | X4: {=ROUND((AZ4+BH4*$J4+INDEX(职业模板!$C$40:$J$60,MATCH($L4,职业模板!$B$40:$B$60,FALSE),MATCH(X$3,职业模板!$C$39:$J$39,FALSE))*AZ4)*(1+INDEX(职业模板!$C$29:$J$34,MATCH($K4,职业模板!$B$29:$B$34,FALSE),MATCH(X$3,职业模板!$C$28:$J$28,FALSE))),2)} -> 38.63 | Y4: {=ROUND((BA4+BI4*$J4+INDEX(职业模板!$C$40:$J$60,MATCH($L4,职业模板!$B$40:$B$60,FALSE),MATCH(Y$3,职业模板!$C$39:$J$39,FALSE))*BA4)*(1+INDEX(职业模板!$C$29:$J$34,MATCH($K4,职业模板!$B$29:$B$34,FALSE),MATCH(Y$3,职业模板!$C$28:$J$28,FALSE))),2)} -> 61.2 | Z4: {=ROUND((BB4+BJ4*$J4+INDEX(职业模板!$C$40:$J$60,MATCH($L4,职业模板!$B$40:$B$60,FALSE),MATCH(Z$3,职业模板!$C$39:$J$39,FALSE))*BB4)*(1+INDEX(职业模板!$C$29:$J$34,MATCH($K4,职业模板!$B$29:$B$34,FALSE),MATCH(Z$3,职业模板!$C$28:$J$28,FALSE))),2)} -> 40.8 | AA4: {=ROUND((BC4+BK4*$J4+INDEX(职业模板!$C$40:$J$60,MATCH($L4,职业模板!$B$40:$B$60,FALSE),MATCH(AA$3,职业模板!$C$39:$J$39,FALSE))*BC4)*(1+INDEX(职业模板!$C$29:$J$34,MATCH($K4,职业模板!$B$29:$B$34,FALSE),MATCH(AA$3,职业模板!$C$28:$J$28,FALSE))),2)} -> 60.6 | AB4: {=ROUND((BD4+BL4*$J4+INDEX(职业模板!$C$40:$J$60,MATCH($L4,职业模板!$B$40:$B$60,FALSE),MATCH(AB$3,职业模板!$C$39:$J$39,FALSE))*BD4)*(1+INDEX(职业模板!$C$29:$J$34,MATCH($K4,职业模板!$B$29:$B$34,FALSE),MATCH(AB$3,职业模板!$C$28:$J$28,FALSE))),2)} -> 60.6 | AC4: {=ROUND((BE4+BM4*$J4+INDEX(职业模板!$C$40:$J$60,MATCH($L4,职业模板!$B$40:$B$60,FALSE),MATCH(AC$3,职业模板!$C$39:$J$39,FALSE))*BE4)*(1+INDEX(职业模板!$C$29:$J$34,MATCH($K4,职业模板!$B$29:$B$34,FALSE),MATCH(AC$3,职业模板!$C$28:$J$28,FALSE))),2)} -> 60.6 | AD4: 1.5 | AE4: 2 | AX4: {=IFERROR(INDEX(属性分配!$C$4:$J$4,MATCH(AX$3,属性分配!$C$3:$J$3,FALSE))*INDEX(职业模板!$C$5:$J$12,MATCH($C4,职业模板!$B$5:$B$12,FALSE),MATCH(AX$3,职业模板!$C$3:$J$3,FALSE))*$F4*N4,"")} -> 405 | AY4: {=IFERROR(INDEX(属性分配!$C$4:$J$4,MATCH(AY$3,属性分配!$C$3:$J$3,FALSE))*INDEX(职业模板!$C$5:$J$12,MATCH($C4,职业模板!$B$5:$B$12,FALSE),MATCH(AY$3,职业模板!$C$3:$J$3,FALSE))*$F4*O4,"")} -> 40 | AZ4: {=IFERROR(INDEX(属性分配!$C$4:$J$4,MATCH(AZ$3,属性分配!$C$3:$J$3,FALSE))*INDEX(职业模板!$C$5:$J$12,MATCH($C4,职业模板!$B$5:$B$12,FALSE),MATCH(AZ$3,职业模板!$C$3:$J$3,FALSE))*$F4*P4,"")} -> 37.5 | BA4: {=IFERROR(INDEX(属性分配!$C$4:$J$4,MATCH(BA$3,属性分配!$C$3:$J$3,FALSE))*INDEX(职业模板!$C$5:$J$12,MATCH($C4,职业模板!$B$5:$B$12,FALSE),MATCH(BA$3,职业模板!$C$3:$J$3,FALSE))*$F4*Q4,"")} -> 60 | BB4: {=IFERROR(INDEX(属性分配!$C$4:$J$4,MATCH(BB$3,属性分配!$C$3:$J$3,FALSE))*INDEX(职业模板!$C$5:$J$12,MATCH($C4,职业模板!$B$5:$B$12,FALSE),MATCH(BB$3,职业模板!$C$3:$J$3,FALSE))*$F4*R4,"")} -> 40 | BC4: {=IFERROR(INDEX(属性分配!$C$4:$J$4,MATCH(BC$3,属性分配!$C$3:$J$3,FALSE))*INDEX(职业模板!$C$5:$J$12,MATCH($C4,职业模板!$B$5:$B$12,FALSE),MATCH(BC$3,职业模板!$C$3:$J$3,FALSE))*$F4*S4,"")} -> 60 | BD4: {=IFERROR(INDEX(属性分配!$C$4:$J$4,MATCH(BD$3,属性分配!$C$3:$J$3,FALSE))*INDEX(职业模板!$C$5:$J$12,MATCH($C4,职业模板!$B$5:$B$12,FALSE),MATCH(BD$3,职业模板!$C$3:$J$3,FALSE))*$F4*T4,"")} -> 60 | BE4: {=IFERROR(INDEX(属性分配!$C$4:$J$4,MATCH(BE$3,属性分配!$C$3:$J$3,FALSE))*INDEX(职业模板!$C$5:$J$12,MATCH($C4,职业模板!$B$5:$B$12,FALSE),MATCH(BE$3,职业模板!$C$3:$J$3,FALSE))*$F4*U4,"")} -> 60 | BF4: {=IFERROR(INDEX(属性分配!$C$11:$J$11,MATCH(BF$3,属性分配!$C$3:$J$3,FALSE))/职业模板!$E$16*AX4,"")} -> 12.15 | BG4: {=IFERROR(INDEX(属性分配!$C$11:$J$11,MATCH(BG$3,属性分配!$C$3:$J$3,FALSE))/职业模板!$E$16*AY4,"")} -> 1.2 | BH4: {=IFERROR(INDEX(属性分配!$C$11:$J$11,MATCH(BH$3,属性分配!$C$3:$J$3,FALSE))/职业模板!$E$16*AZ4,"")} -> 1.125 | BI4: {=IFERROR(INDEX(属性分配!$C$11:$J$11,MATCH(BI$3,属性分配!$C$3:$J$3,FALSE))/职业模板!$E$16*BA4,"")} -> 1.2 | BJ4: {=IFERROR(INDEX(属性分配!$C$11:$J$11,MATCH(BJ$3,属性分配!$C$3:$J$3,FALSE))/职业模板!$E$16*BB4,"")} -> 0.8 | BK4: {=IFERROR(INDEX(属性分配!$C$11:$J$11,MATCH(BK$3,属性分配!$C$3:$J$3,FALSE))/职业模板!$E$16*BC4,"")} -> 0.6 | BL4: {=IFERROR(INDEX(属性分配!$C$11:$J$11,MATCH(BL$3,属性分配!$C$3:$J$3,FALSE))/职业模板!$E$16*BD4,"")} -> 0.6 | BM4: {=IFERROR(INDEX(属性分配!$C$11:$J$11,MATCH(BM$3,属性分配!$C$3:$J$3,FALSE))/职业模板!$E$16*BE4,"")} -> 0.6 | BN4: {=IFERROR(ROUND((AX4+BF4*职业模板!$E$16)*(1+INDEX(职业模板!$C$29:$J$34,MATCH($K4,职业模板!$B$29:$B$34,FALSE),MATCH(V$3,职业模板!$C$28:$J$28,FALSE))+INDEX(职业模板!$C$40:$J$60,MATCH($L4,职业模板!$B$40:$B$60,FALSE),MATCH(V$3,职业模板!$C$39:$J$39,FALSE))),2),"")} -> 1620 | BO4: {=IFERROR(ROUND((AY4+BG4*职业模板!$E$16)*(1+INDEX(职业模板!$C$29:$J$34,MATCH($K4,职业模板!$B$29:$B$34,FALSE),MATCH(W$3,职业模板!$C$28:$J$28,FALSE))+INDEX(职业模板!$C$40:$J$60,MATCH($L4,职业模板!$B$40:$B$60,FALSE),MATCH(W$3,职业模板!$C$39:$J$39,FALSE))),2),"")} -> 160 | BP4: {=IFERROR(ROUND((AZ4+BH4*职业模板!$E$16)*(1+INDEX(职业模板!$C$29:$J$34,MATCH($K4,职业模板!$B$29:$B$34,FALSE),MATCH(X$3,职业模板!$C$28:$J$28,FALSE))+INDEX(职业模板!$C$40:$J$60,MATCH($L4,职业模板!$B$40:$B$60,FALSE),MATCH(X$3,职业模板!$C$39:$J$39,FALSE))),2),"")} -> 150 | BQ4: {=IFERROR(ROUND((BA4+BI4*职业模板!$E$16)*(1+INDEX(职业模板!$C$29:$J$34,MATCH($K4,职业模板!$B$29:$B$34,FALSE),MATCH(Y$3,职业模板!$C$28:$J$28,FALSE))+INDEX(职业模板!$C$40:$J$60,MATCH($L4,职业模板!$B$40:$B$60,FALSE),MATCH(Y$3,职业模板!$C$39:$J$39,FALSE))),2),"")} -> 180 | BR4: {=IFERROR(ROUND((BB4+BJ4*职业模板!$E$16)*(1+INDEX(职业模板!$C$29:$J$34,MATCH($K4,职业模板!$B$29:$B$34,FALSE),MATCH(Z$3,职业模板!$C$28:$J$28,FALSE))+INDEX(职业模板!$C$40:$J$60,MATCH($L4,职业模板!$B$40:$B$60,FALSE),MATCH(Z$3,职业模板!$C$39:$J$39,FALSE))),2),"")} -> 120 | BS4: {=IFERROR(ROUND((BC4+BK4*职业模板!$E$16)*(1+INDEX(职业模板!$C$29:$J$34,MATCH($K4,职业模板!$B$29:$B$34,FALSE),MATCH(AA$3,职业模板!$C$28:$J$28,FALSE))+INDEX(职业模板!$C$40:$J$60,MATCH($L4,职业模板!$B$40:$B$60,FALSE),MATCH(AA$3,职业模板!$C$39:$J$39,FALSE))),2),"")} -> 120 | BT4: {=IFERROR(ROUND((BD4+BL4*职业模板!$E$16)*(1+INDEX(职业模板!$C$29:$J$34,MATCH($K4,职业模板!$B$29:$B$34,FALSE),MATCH(AB$3,职业模板!$C$28:$J$28,FALSE))+INDEX(职业模板!$C$40:$J$60,MATCH($L4,职业模板!$B$40:$B$60,FALSE),MATCH(AB$3,职业模板!$C$39:$J$39,FALSE))),2),"")} -> 120 | BU4: {=IFERROR(ROUND((BE4+BM4*职业模板!$E$16)*(1+INDEX(职业模板!$C$29:$J$34,MATCH($K4,职业模板!$B$29:$B$34,FALSE),MATCH(AC$3,职业模板!$C$28:$J$28,FALSE))+INDEX(职业模板!$C$40:$J$60,MATCH($L4,职业模板!$B$40:$B$60,FALSE),MATCH(AC$3,职业模板!$C$39:$J$39,FALSE))),2),"")} -> 120 | BV4: {=SUMPRODUCT(BN4:BR4,属性分配!$C$7:$G$7)} -> 2650 | BW4: {=IFERROR((AX4+BF4*职业模板!$E$16)*(1+INDEX(职业模板!$C$34:$J$34,MATCH(V$3,职业模板!$C$28:$J$28,FALSE))+INDEX(职业模板!$C$60:$J$60,MATCH(V$3,职业模板!$C$39:$J$39,FALSE))),"")} -> 9720 | BX4: {=IFERROR((AY4+BG4*职业模板!$E$16)*(1+INDEX(职业模板!$C$34:$J$34,MATCH(W$3,职业模板!$C$28:$J$28,FALSE))+INDEX(职业模板!$C$60:$J$60,MATCH(W$3,职业模板!$C$39:$J$39,FALSE))),"")} -> 800 | BY4: {=IFERROR((AZ4+BH4*职业模板!$E$16)*(1+INDEX(职业模板!$C$34:$J$34,MATCH(X$3,职业模板!$C$28:$J$28,FALSE))+INDEX(职业模板!$C$60:$J$60,MATCH(X$3,职业模板!$C$39:$J$39,FALSE))),"")} -> 750 | BZ4: {=IFERROR((BA4+BI4*职业模板!$E$16)*(1+INDEX(职业模板!$C$34:$J$34,MATCH(Y$3,职业模板!$C$28:$J$28,FALSE))+INDEX(职业模板!$C$60:$J$60,MATCH(Y$3,职业模板!$C$39:$J$39,FALSE))),"")} -> 720 | CA4: {=IFERROR((BB4+BJ4*职业模板!$E$16)*(1+INDEX(职业模板!$C$34:$J$34,MATCH(Z$3,职业模板!$C$28:$J$28,FALSE))+INDEX(职业模板!$C$60:$J$60,MATCH(Z$3,职业模板!$C$39:$J$39,FALSE))),"")} -> 480 | CB4: {=IFERROR((BC4+BK4*职业模板!$E$16)*(1+INDEX(职业模板!$C$34:$J$34,MATCH(AA$3,职业模板!$C$28:$J$28,FALSE))+INDEX(职业模板!$C$60:$J$60,MATCH(AA$3,职业模板!$C$39:$J$39,FALSE))),"")} -> 210 | CC4: {=IFERROR((BD4+BL4*职业模板!$E$16)*(1+INDEX(职业模板!$C$34:$J$34,MATCH(AB$3,职业模板!$C$28:$J$28,FALSE))+INDEX(职业模板!$C$60:$J$60,MATCH(AB$3,职业模板!$C$39:$J$39,FALSE))),"")} -> 210 | CD4: {=IFERROR((BE4+BM4*职业模板!$E$16)*(1+INDEX(职业模板!$C$34:$J$34,MATCH(AC$3,职业模板!$C$28:$J$28,FALSE))+INDEX(职业模板!$C$60:$J$60,MATCH(AC$3,职业模板!$C$39:$J$39,FALSE))),"")} -> 210 | CE4: {=IF(SUMPRODUCT(BW4:CA4,属性分配!$C$7:$G$7)=0,"",SUMPRODUCT(BW4:CA4,属性分配!$C$7:$G$7))} -> 13460
A5: 10001 | B5: 模板2 | C5: 战士 | D5: 4 | E5: 4 | F5: 1 | G5: 20 | H5: 5 | I5: 0 | J5: 1 | K5: 0 | L5: 0 | M5: 0 | N5: 1 | O5: 1 | P5: 1 | Q5: 1 | R5: 1 | S5: 1 | T5: 1 | U5: 1 | V5: {=ROUND((AX5+BF5*$J5+INDEX(职业模板!$C$40:$J$60,MATCH($L5,职业模板!$B$40:$B$60,FALSE),MATCH(V$3,职业模板!$C$39:$J$39,FALSE))*AX5)*(1+INDEX(职业模板!$C$29:$J$34,MATCH($K5,职业模板!$B$29:$B$34,FALSE),MATCH(V$3,职业模板!$C$28:$J$28,FALSE))),2)} -> 324.45 | W5: {=ROUND((AY5+BG5*$J5+INDEX(职业模板!$C$40:$J$60,MATCH($L5,职业模板!$B$40:$B$60,FALSE),MATCH(W$3,职业模板!$C$39:$J$39,FALSE))*AY5)*(1+INDEX(职业模板!$C$29:$J$34,MATCH($K5,职业模板!$B$29:$B$34,FALSE),MATCH(W$3,职业模板!$C$28:$J$28,FALSE))),2)} -> 56.65 | X5: {=ROUND((AZ5+BH5*$J5+INDEX(职业模板!$C$40:$J$60,MATCH($L5,职业模板!$B$40:$B$60,FALSE),MATCH(X$3,职业模板!$C$39:$J$39,FALSE))*AZ5)*(1+INDEX(职业模板!$C$29:$J$34,MATCH($K5,职业模板!$B$29:$B$34,FALSE),MATCH(X$3,职业模板!$C$28:$J$28,FALSE))),2)} -> 41.2 | Y5: {=ROUND((BA5+BI5*$J5+INDEX(职业模板!$C$40:$J$60,MATCH($L5,职业模板!$B$40:$B$60,FALSE),MATCH(Y$3,职业模板!$C$39:$J$39,FALSE))*BA5)*(1+INDEX(职业模板!$C$29:$J$34,MATCH($K5,职业模板!$B$29:$B$34,FALSE),MATCH(Y$3,职业模板!$C$28:$J$28,FALSE))),2)} -> 51 | Z5: {=ROUND((BB5+BJ5*$J5+INDEX(职业模板!$C$40:$J$60,MATCH($L5,职业模板!$B$40:$B$60,FALSE),MATCH(Z$3,职业模板!$C$39:$J$39,FALSE))*BB5)*(1+INDEX(职业模板!$C$29:$J$34,MATCH($K5,职业模板!$B$29:$B$34,FALSE),MATCH(Z$3,职业模板!$C$28:$J$28,FALSE))),2)} -> 48.45 | AA5: {=ROUND((BC5+BK5*$J5+INDEX(职业模板!$C$40:$J$60,MATCH($L5,职业模板!$B$40:$B$60,FALSE),MATCH(AA$3,职业模板!$C$39:$J$39,FALSE))*BC5)*(1+INDEX(职业模板!$C$29:$J$34,MATCH($K5,职业模板!$B$29:$B$34,FALSE),MATCH(AA$3,职业模板!$C$28:$J$28,FALSE))),2)} -> 70.7 | AB5: {=ROUND((BD5+BL5*$J5+INDEX(职业模板!$C$40:$J$60,MATCH($L5,职业模板!$B$40:$B$60,FALSE),MATCH(AB$3,职业模板!$C$39:$J$39,FALSE))*BD5)*(1+INDEX(职业模板!$C$29:$J$34,MATCH($K5,职业模板!$B$29:$B$34,FALSE),MATCH(AB$3,职业模板!$C$28:$J$28,FALSE))),2)} -> 50.5 | AC5: {=ROUND((BE5+BM5*$J5+INDEX(职业模板!$C$40:$J$60,MATCH($L5,职业模板!$B$40:$B$60,FALSE),MATCH(AC$3,职业模板!$C$39:$J$39,FALSE))*BE5)*(1+INDEX(职业模板!$C$29:$J$34,MATCH($K5,职业模板!$B$29:$B$34,FALSE),MATCH(AC$3,职业模板!$C$28:$J$28,FALSE))),2)} -> 60.6 | AD5: 1.5 | AE5: 2 | AX5: {=IFERROR(INDEX(属性分配!$C$4:$J$4,MATCH(AX$3,属性分配!$C$3:$J$3,FALSE))*INDEX(职业模板!$C$5:$J$12,MATCH($C5,职业模板!$B$5:$B$12,FALSE),MATCH(AX$3,职业模板!$C$3:$J$3,FALSE))*$F5*N5,"")} -> 315 | AY5: {=IFERROR(INDEX(属性分配!$C$4:$J$4,MATCH(AY$3,属性分配!$C$3:$J$3,FALSE))*INDEX(职业模板!$C$5:$J$12,MATCH($C5,职业模板!$B$5:$B$12,FALSE),MATCH(AY$3,职业模板!$C$3:$J$3,FALSE))*$F5*O5,"")} -> 55 | AZ5: {=IFERROR(INDEX(属性分配!$C$4:$J$4,MATCH(AZ$3,属性分配!$C$3:$J$3,FALSE))*INDEX(职业模板!$C$5:$J$12,MATCH($C5,职业模板!$B$5:$B$12,FALSE),MATCH(AZ$3,职业模板!$C$3:$J$3,FALSE))*$F5*P5,"")} -> 40 | BA5: {=IFERROR(INDEX(属性分配!$C$4:$J$4,MATCH(BA$3,属性分配!$C$3:$J$3,FALSE))*INDEX(职业模板!$C$5:$J$12,MATCH($C5,职业模板!$B$5:$B$12,FALSE),MATCH(BA$3,职业模板!$C$3:$J$3,FALSE))*$F5*Q5,"")} -> 50 | BB5: {=IFERROR(INDEX(属性分配!$C$4:$J$4,MATCH(BB$3,属性分配!$C$3:$J$3,FALSE))*INDEX(职业模板!$C$5:$J$12,MATCH($C5,职业模板!$B$5:$B$12,FALSE),MATCH(BB$3,职业模板!$C$3:$J$3,FALSE))*$F5*R5,"")} -> 47.5 | BC5: {=IFERROR(INDEX(属性分配!$C$4:$J$4,MATCH(BC$3,属性分配!$C$3:$J$3,FALSE))*INDEX(职业模板!$C$5:$J$12,MATCH($C5,职业模板!$B$5:$B$12,FALSE),MATCH(BC$3,职业模板!$C$3:$J$3,FALSE))*$F5*S5,"")} -> 70 | BD5: {=IFERROR(INDEX(属性分配!$C$4:$J$4,MATCH(BD$3,属性分配!$C$3:$J$3,FALSE))*INDEX(职业模板!$C$5:$J$12,MATCH($C5,职业模板!$B$5:$B$12,FALSE),MATCH(BD$3,职业模板!$C$3:$J$3,FALSE))*$F5*T5,"")} -> 50 | BE5: {=IFERROR(INDEX(属性分配!$C$4:$J$4,MATCH(BE$3,属性分配!$C$3:$J$3,FALSE))*INDEX(职业模板!$C$5:$J$12,MATCH($C5,职业模板!$B$5:$B$12,FALSE),MATCH(BE$3,职业模板!$C$3:$J$3,FALSE))*$F5*U5,"")} -> 60 | BF5: {=IFERROR(INDEX(属性分配!$C$11:$J$11,MATCH(BF$3,属性分配!$C$3:$J$3,FALSE))/职业模板!$E$16*AX5,"")} -> 9.45 | BG5: {=IFERROR(INDEX(属性分配!$C$11:$J$11,MATCH(BG$3,属性分配!$C$3:$J$3,FALSE))/职业模板!$E$16*AY5,"")} -> 1.65 | BH5: {=IFERROR(INDEX(属性分配!$C$11:$J$11,MATCH(BH$3,属性分配!$C$3:$J$3,FALSE))/职业模板!$E$16*AZ5,"")} -> 1.2 | BI5: {=IFERROR(INDEX(属性分配!$C$11:$J$11,MATCH(BI$3,属性分配!$C$3:$J$3,FALSE))/职业模板!$E$16*BA5,"")} -> 1 | BJ5: {=IFERROR(INDEX(属性分配!$C$11:$J$11,MATCH(BJ$3,属性分配!$C$3:$J$3,FALSE))/职业模板!$E$16*BB5,"")} -> 0.95 | BK5: {=IFERROR(INDEX(属性分配!$C$11:$J$11,MATCH(BK$3,属性分配!$C$3:$J$3,FALSE))/职业模板!$E$16*BC5,"")} -> 0.7 | BL5: {=IFERROR(INDEX(属性分配!$C$11:$J$11,MATCH(BL$3,属性分配!$C$3:$J$3,FALSE))/职业模板!$E$16*BD5,"")} -> 0.5 | BM5: {=IFERROR(INDEX(属性分配!$C$11:$J$11,MATCH(BM$3,属性分配!$C$3:$J$3,FALSE))/职业模板!$E$16*BE5,"")} -> 0.6 | BN5: {=IFERROR(ROUND((AX5+BF5*职业模板!$E$16)*(1+INDEX(职业模板!$C$29:$J$34,MATCH($K5,职业模板!$B$29:$B$34,FALSE),MATCH(V$3,职业模板!$C$28:$J$28,FALSE))+INDEX(职业模板!$C$40:$J$60,MATCH($L5,职业模板!$B$40:$B$60,FALSE),MATCH(V$3,职业模板!$C$39:$J$39,FALSE))),2),"")} -> 1260 | BO5: {=IFERROR(ROUND((AY5+BG5*职业模板!$E$16)*(1+INDEX(职业模板!$C$29:$J$34,MATCH($K5,职业模板!$B$29:$B$34,FALSE),MATCH(W$3,职业模板!$C$28:$J$28,FALSE))+INDEX(职业模板!$C$40:$J$60,MATCH($L5,职业模板!$B$40:$B$60,FALSE),MATCH(W$3,职业模板!$C$39:$J$39,FALSE))),2),"")} -> 220 | BP5: {=IFERROR(ROUND((AZ5+BH5*职业模板!$E$16)*(1+INDEX(职业模板!$C$29:$J$34,MATCH($K5,职业模板!$B$29:$B$34,FALSE),MATCH(X$3,职业模板!$C$28:$J$28,FALSE))+INDEX(职业模板!$C$40:$J$60,MATCH($L5,职业模板!$B$40:$B$60,FALSE),MATCH(X$3,职业模板!$C$39:$J$39,FALSE))),2),"")} -> 160 | BQ5: {=IFERROR(ROUND((BA5+BI5*职业模板!$E$16)*(1+INDEX(职业模板!$C$29:$J$34,MATCH($K5,职业模板!$B$29:$B$34,FALSE),MATCH(Y$3,职业模板!$C$28:$J$28,FALSE))+INDEX(职业模板!$C$40:$J$60,MATCH($L5,职业模板!$B$40:$B$60,FALSE),MATCH(Y$3,职业模板!$C$39:$J$39,FALSE))),2),"")} -> 150 | BR5: {=IFERROR(ROUND((BB5+BJ5*职业模板!$E$16)*(1+INDEX(职业模板!$C$29:$J$34,MATCH($K5,职业模板!$B$29:$B$34,FALSE),MATCH(Z$3,职业模板!$C$28:$J$28,FALSE))+INDEX(职业模板!$C$40:$J$60,MATCH($L5,职业模板!$B$40:$B$60,FALSE),MATCH(Z$3,职业模板!$C$39:$J$39,FALSE))),2),"")} -> 142.5 | BS5: {=IFERROR(ROUND((BC5+BK5*职业模板!$E$16)*(1+INDEX(职业模板!$C$29:$J$34,MATCH($K5,职业模板!$B$29:$B$34,FALSE),MATCH(AA$3,职业模板!$C$28:$J$28,FALSE))+INDEX(职业模板!$C$40:$J$60,MATCH($L5,职业模板!$B$40:$B$60,FALSE),MATCH(AA$3,职业模板!$C$39:$J$39,FALSE))),2),"")} -> 140 | BT5: {=IFERROR(ROUND((BD5+BL5*职业模板!$E$16)*(1+INDEX(职业模板!$C$29:$J$34,MATCH($K5,职业模板!$B$29:$B$34,FALSE),MATCH(AB$3,职业模板!$C$28:$J$28,FALSE))+INDEX(职业模板!$C$40:$J$60,MATCH($L5,职业模板!$B$40:$B$60,FALSE),MATCH(AB$3,职业模板!$C$39:$J$39,FALSE))),2),"")} -> 100 | BU5: {=IFERROR(ROUND((BE5+BM5*职业模板!$E$16)*(1+INDEX(职业模板!$C$29:$J$34,MATCH($K5,职业模板!$B$29:$B$34,FALSE),MATCH(AC$3,职业模板!$C$28:$J$28,FALSE))+INDEX(职业模板!$C$40:$J$60,MATCH($L5,职业模板!$B$40:$B$60,FALSE),MATCH(AC$3,职业模板!$C$39:$J$39,FALSE))),2),"")} -> 120 | BV5: {=IF(SUMPRODUCT($BN5:$BR5,属性分配!$C$7:$G$7)=0,"",SUMPRODUCT($BN5:$BR5,属性分配!$C$7:$G$7))} -> 2735 | BW5: {=IFERROR((AX5+BF5*职业模板!$E$16)*(1+INDEX(职业模板!$C$34:$J$34,MATCH(V$3,职业模板!$C$28:$J$28,FALSE))+INDEX(职业模板!$C$60:$J$60,MATCH(V$3,职业模板!$C$39:$J$39,FALSE))),"")} -> 7560 | BX5: {=IFERROR((AY5+BG5*职业模板!$E$16)*(1+INDEX(职业模板!$C$34:$J$34,MATCH(W$3,职业模板!$C$28:$J$28,FALSE))+INDEX(职业模板!$C$60:$J$60,MATCH(W$3,职业模板!$C$39:$J$39,FALSE))),"")} -> 1100 | BY5: {=IFERROR((AZ5+BH5*职业模板!$E$16)*(1+INDEX(职业模板!$C$34:$J$34,MATCH(X$3,职业模板!$C$28:$J$28,FALSE))+INDEX(职业模板!$C$60:$J$60,MATCH(X$3,职业模板!$C$39:$J$39,FALSE))),"")} -> 800 | BZ5: {=IFERROR((BA5+BI5*职业模板!$E$16)*(1+INDEX(职业模板!$C$34:$J$34,MATCH(Y$3,职业模板!$C$28:$J$28,FALSE))+INDEX(职业模板!$C$60:$J$60,MATCH(Y$3,职业模板!$C$39:$J$39,FALSE))),"")} -> 600 | CA5: {=IFERROR((BB5+BJ5*职业模板!$E$16)*(1+INDEX(职业模板!$C$34:$J$34,MATCH(Z$3,职业模板!$C$28:$J$28,FALSE))+INDEX(职业模板!$C$60:$J$60,MATCH(Z$3,职业模板!$C$39:$J$39,FALSE))),"")} -> 570 | CB5: {=IFERROR((BC5+BK5*职业模板!$E$16)*(1+INDEX(职业模板!$C$34:$J$34,MATCH(AA$3,职业模板!$C$28:$J$28,FALSE))+INDEX(职业模板!$C$60:$J$60,MATCH(AA$3,职业模板!$C$39:$J$39,FALSE))),"")} -> 245 | CC5: {=IFERROR((BD5+BL5*职业模板!$E$16)*(1+INDEX(职业模板!$C$34:$J$34,MATCH(AB$3,职业模板!$C$28:$J$28,FALSE))+INDEX(职业模板!$C$60:$J$60,MATCH(AB$3,职业模板!$C$39:$J$39,FALSE))),"")} -> 175 | CD5: {=IFERROR((BE5+BM5*职业模板!$E$16)*(1+INDEX(职业模板!$C$34:$J$34,MATCH(AC$3,职业模板!$C$28:$J$28,FALSE))+INDEX(职业模板!$C$60:$J$60,MATCH(AC$3,职业模板!$C$39:$J$39,FALSE))),"")} -> 210 | CE5: {=IF(SUMPRODUCT(BW5:CA5,属性分配!$C$7:$G$7)=0,"",SUMPRODUCT(BW5:CA5,属性分配!$C$7:$G$7))} -> 13720
A6: 10002 | B6: 模板3 | C6: 法坦 | D6: 4 | E6: 4 | F6: 1 | G6: 20 | H6: 5 | I6: 0 | J6: 1 | K6: 0 | L6: 0 | M6: 0 | N6: 1 | O6: 1 | P6: 1 | Q6: 1 | R6: 1 | S6: 1 | T6: 1 | U6: 1 | V6: {=ROUND((AX6+BF6*$J6+INDEX(职业模板!$C$40:$J$60,MATCH($L6,职业模板!$B$40:$B$60,FALSE),MATCH(V$3,职业模板!$C$39:$J$39,FALSE))*AX6)*(1+INDEX(职业模板!$C$29:$J$34,MATCH($K6,职业模板!$B$29:$B$34,FALSE),MATCH(V$3,职业模板!$C$28:$J$28,FALSE))),2)} -> 401.7 | W6: {=ROUND((AY6+BG6*$J6+INDEX(职业模板!$C$40:$J$60,MATCH($L6,职业模板!$B$40:$B$60,FALSE),MATCH(W$3,职业模板!$C$39:$J$39,FALSE))*AY6)*(1+INDEX(职业模板!$C$29:$J$34,MATCH($K6,职业模板!$B$29:$B$34,FALSE),MATCH(W$3,职业模板!$C$28:$J$28,FALSE))),2)} -> 38.63 | X6: {=ROUND((AZ6+BH6*$J6+INDEX(职业模板!$C$40:$J$60,MATCH($L6,职业模板!$B$40:$B$60,FALSE),MATCH(X$3,职业模板!$C$39:$J$39,FALSE))*AZ6)*(1+INDEX(职业模板!$C$29:$J$34,MATCH($K6,职业模板!$B$29:$B$34,FALSE),MATCH(X$3,职业模板!$C$28:$J$28,FALSE))),2)} -> 41.2 | Y6: {=ROUND((BA6+BI6*$J6+INDEX(职业模板!$C$40:$J$60,MATCH($L6,职业模板!$B$40:$B$60,FALSE),MATCH(Y$3,职业模板!$C$39:$J$39,FALSE))*BA6)*(1+INDEX(职业模板!$C$29:$J$34,MATCH($K6,职业模板!$B$29:$B$34,FALSE),MATCH(Y$3,职业模板!$C$28:$J$28,FALSE))),2)} -> 48.45 | Z6: {=ROUND((BB6+BJ6*$J6+INDEX(职业模板!$C$40:$J$60,MATCH($L6,职业模板!$B$40:$B$60,FALSE),MATCH(Z$3,职业模板!$C$39:$J$39,FALSE))*BB6)*(1+INDEX(职业模板!$C$29:$J$34,MATCH($K6,职业模板!$B$29:$B$34,FALSE),MATCH(Z$3,职业模板!$C$28:$J$28,FALSE))),2)} -> 61.2 | AA6: {=ROUND((BC6+BK6*$J6+INDEX(职业模板!$C$40:$J$60,MATCH($L6,职业模板!$B$40:$B$60,FALSE),MATCH(AA$3,职业模板!$C$39:$J$39,FALSE))*BC6)*(1+INDEX(职业模板!$C$29:$J$34,MATCH($K6,职业模板!$B$29:$B$34,FALSE),MATCH(AA$3,职业模板!$C$28:$J$28,FALSE))),2)} -> 50.5 | AB6: {=ROUND((BD6+BL6*$J6+INDEX(职业模板!$C$40:$J$60,MATCH($L6,职业模板!$B$40:$B$60,FALSE),MATCH(AB$3,职业模板!$C$39:$J$39,FALSE))*BD6)*(1+INDEX(职业模板!$C$29:$J$34,MATCH($K6,职业模板!$B$29:$B$34,FALSE),MATCH(AB$3,职业模板!$C$28:$J$28,FALSE))),2)} -> 70.7 | AC6: {=ROUND((BE6+BM6*$J6+INDEX(职业模板!$C$40:$J$60,MATCH($L6,职业模板!$B$40:$B$60,FALSE),MATCH(AC$3,职业模板!$C$39:$J$39,FALSE))*BE6)*(1+INDEX(职业模板!$C$29:$J$34,MATCH($K6,职业模板!$B$29:$B$34,FALSE),MATCH(AC$3,职业模板!$C$28:$J$28,FALSE))),2)} -> 60.6 | AD6: 1.5 | AE6: 2 | AX6: {=IFERROR(INDEX(属性分配!$C$4:$J$4,MATCH(AX$3,属性分配!$C$3:$J$3,FALSE))*INDEX(职业模板!$C$5:$J$12,MATCH($C6,职业模板!$B$5:$B$12,FALSE),MATCH(AX$3,职业模板!$C$3:$J$3,FALSE))*$F6*N6,"")} -> 390 | AY6: {=IFERROR(INDEX(属性分配!$C$4:$J$4,MATCH(AY$3,属性分配!$C$3:$J$3,FALSE))*INDEX(职业模板!$C$5:$J$12,MATCH($C6,职业模板!$B$5:$B$12,FALSE),MATCH(AY$3,职业模板!$C$3:$J$3,FALSE))*$F6*O6,"")} -> 37.5 | AZ6: {=IFERROR(INDEX(属性分配!$C$4:$J$4,MATCH(AZ$3,属性分配!$C$3:$J$3,FALSE))*INDEX(职业模板!$C$5:$J$12,MATCH($C6,职业模板!$B$5:$B$12,FALSE),MATCH(AZ$3,职业模板!$C$3:$J$3,FALSE))*$F6*P6,"")} -> 40 | BA6: {=IFERROR(INDEX(属性分配!$C$4:$J$4,MATCH(BA$3,属性分配!$C$3:$J$3,FALSE))*INDEX(职业模板!$C$5:$J$12,MATCH($C6,职业模板!$B$5:$B$12,FALSE),MATCH(BA$3,职业模板!$C$3:$J$3,FALSE))*$F6*Q6,"")} -> 47.5 | BB6: {=IFERROR(INDEX(属性分配!$C$4:$J$4,MATCH(BB$3,属性分配!$C$3:$J$3,FALSE))*INDEX(职业模板!$C$5:$J$12,MATCH($C6,职业模板!$B$5:$B$12,FALSE),MATCH(BB$3,职业模板!$C$3:$J$3,FALSE))*$F6*R6,"")} -> 60 | BC6: {=IFERROR(INDEX(属性分配!$C$4:$J$4,MATCH(BC$3,属性分配!$C$3:$J$3,FALSE))*INDEX(职业模板!$C$5:$J$12,MATCH($C6,职业模板!$B$5:$B$12,FALSE),MATCH(BC$3,职业模板!$C$3:$J$3,FALSE))*$F6*S6,"")} -> 50 | BD6: {=IFERROR(INDEX(属性分配!$C$4:$J$4,MATCH(BD$3,属性分配!$C$3:$J$3,FALSE))*INDEX(职业模板!$C$5:$J$12,MATCH($C6,职业模板!$B$5:$B$12,FALSE),MATCH(BD$3,职业模板!$C$3:$J$3,FALSE))*$F6*T6,"")} -> 70 | BE6: {=IFERROR(INDEX(属性分配!$C$4:$J$4,MATCH(BE$3,属性分配!$C$3:$J$3,FALSE))*INDEX(职业模板!$C$5:$J$12,MATCH($C6,职业模板!$B$5:$B$12,FALSE),MATCH(BE$3,职业模板!$C$3:$J$3,FALSE))*$F6*U6,"")} -> 60 | BF6: {=IFERROR(INDEX(属性分配!$C$11:$J$11,MATCH(BF$3,属性分配!$C$3:$J$3,FALSE))/职业模板!$E$16*AX6,"")} -> 11.7 | BG6: {=IFERROR(INDEX(属性分配!$C$11:$J$11,MATCH(BG$3,属性分配!$C$3:$J$3,FALSE))/职业模板!$E$16*AY6,"")} -> 1.125 | BH6: {=IFERROR(INDEX(属性分配!$C$11:$J$11,MATCH(BH$3,属性分配!$C$3:$J$3,FALSE))/职业模板!$E$16*AZ6,"")} -> 1.2 | BI6: {=IFERROR(INDEX(属性分配!$C$11:$J$11,MATCH(BI$3,属性分配!$C$3:$J$3,FALSE))/职业模板!$E$16*BA6,"")} -> 0.95 | BJ6: {=IFERROR(INDEX(属性分配!$C$11:$J$11,MATCH(BJ$3,属性分配!$C$3:$J$3,FALSE))/职业模板!$E$16*BB6,"")} -> 1.2 | BK6: {=IFERROR(INDEX(属性分配!$C$11:$J$11,MATCH(BK$3,属性分配!$C$3:$J$3,FALSE))/职业模板!$E$16*BC6,"")} -> 0.5 | BL6: {=IFERROR(INDEX(属性分配!$C$11:$J$11,MATCH(BL$3,属性分配!$C$3:$J$3,FALSE))/职业模板!$E$16*BD6,"")} -> 0.7 | BM6: {=IFERROR(INDEX(属性分配!$C$11:$J$11,MATCH(BM$3,属性分配!$C$3:$J$3,FALSE))/职业模板!$E$16*BE6,"")} -> 0.6 | BN6: {=IFERROR(ROUND((AX6+BF6*职业模板!$E$16)*(1+INDEX(职业模板!$C$29:$J$34,MATCH($K6,职业模板!$B$29:$B$34,FALSE),MATCH(V$3,职业模板!$C$28:$J$28,FALSE))+INDEX(职业模板!$C$40:$J$60,MATCH($L6,职业模板!$B$40:$B$60,FALSE),MATCH(V$3,职业模板!$C$39:$J$39,FALSE))),2),"")} -> 1560 | BO6: {=IFERROR(ROUND((AY6+BG6*职业模板!$E$16)*(1+INDEX(职业模板!$C$29:$J$34,MATCH($K6,职业模板!$B$29:$B$34,FALSE),MATCH(W$3,职业模板!$C$28:$J$28,FALSE))+INDEX(职业模板!$C$40:$J$60,MATCH($L6,职业模板!$B$40:$B$60,FALSE),MATCH(W$3,职业模板!$C$39:$J$39,FALSE))),2),"")} -> 150 | BP6: {=IFERROR(ROUND((AZ6+BH6*职业模板!$E$16)*(1+INDEX(职业模板!$C$29:$J$34,MATCH($K6,职业模板!$B$29:$B$34,FALSE),MATCH(X$3,职业模板!$C$28:$J$28,FALSE))+INDEX(职业模板!$C$40:$J$60,MATCH($L6,职业模板!$B$40:$B$60,FALSE),MATCH(X$3,职业模板!$C$39:$J$39,FALSE))),2),"")} -> 160 | BQ6: {=IFERROR(ROUND((BA6+BI6*职业模板!$E$16)*(1+INDEX(职业模板!$C$29:$J$34,MATCH($K6,职业模板!$B$29:$B$34,FALSE),MATCH(Y$3,职业模板!$C$28:$J$28,FALSE))+INDEX(职业模板!$C$40:$J$60,MATCH($L6,职业模板!$B$40:$B$60,FALSE),MATCH(Y$3,职业模板!$C$39:$J$39,FALSE))),2),"")} -> 142.5 | BR6: {=IFERROR(ROUND((BB6+BJ6*职业模板!$E$16)*(1+INDEX(职业模板!$C$29:$J$34,MATCH($K6,职业模板!$B$29:$B$34,FALSE),MATCH(Z$3,职业模板!$C$28:$J$28,FALSE))+INDEX(职业模板!$C$40:$J$60,MATCH($L6,职业模板!$B$40:$B$60,FALSE),MATCH(Z$3,职业模板!$C$39:$J$39,FALSE))),2),"")} -> 180 | BS6: {=IFERROR(ROUND((BC6+BK6*职业模板!$E$16)*(1+INDEX(职业模板!$C$29:$J$34,MATCH($K6,职业模板!$B$29:$B$34,FALSE),MATCH(AA$3,职业模板!$C$28:$J$28,FALSE))+INDEX(职业模板!$C$40:$J$60,MATCH($L6,职业模板!$B$40:$B$60,FALSE),MATCH(AA$3,职业模板!$C$39:$J$39,FALSE))),2),"")} -> 100 | BT6: {=IFERROR(ROUND((BD6+BL6*职业模板!$E$16)*(1+INDEX(职业模板!$C$29:$J$34,MATCH($K6,职业模板!$B$29:$B$34,FALSE),MATCH(AB$3,职业模板!$C$28:$J$28,FALSE))+INDEX(职业模板!$C$40:$J$60,MATCH($L6,职业模板!$B$40:$B$60,FALSE),MATCH(AB$3,职业模板!$C$39:$J$39,FALSE))),2),"")} -> 140 | BU6: {=IFERROR(ROUND((BE6+BM6*职业模板!$E$16)*(1+INDEX(职业模板!$C$29:$J$34,MATCH($K6,职业模板!$B$29:$B$34,FALSE),MATCH(AC$3,职业模板!$C$28:$J$28,FALSE))+INDEX(职业模板!$C$40:$J$60,MATCH($L6,职业模板!$B$40:$B$60,FALSE),MATCH(AC$3,职业模板!$C$39:$J$39,FALSE))),2),"")} -> 120 | BV6: {=IF(SUMPRODUCT($BN6:$BR6,属性分配!$C$7:$G$7)=0,"",SUMPRODUCT($BN6:$BR6,属性分配!$C$7:$G$7))} -> 2665 | BW6: {=IFERROR((AX6+BF6*职业模板!$E$16)*(1+INDEX(职业模板!$C$34:$J$34,MATCH(V$3,职业模板!$C$28:$J$28,FALSE))+INDEX(职业模板!$C$60:$J$60,MATCH(V$3,职业模板!$C$39:$J$39,FALSE))),"")} -> 9360 | BX6: {=IFERROR((AY6+BG6*职业模板!$E$16)*(1+INDEX(职业模板!$C$34:$J$34,MATCH(W$3,职业模板!$C$28:$J$28,FALSE))+INDEX(职业模板!$C$60:$J$60,MATCH(W$3,职业模板!$C$39:$J$39,FALSE))),"")} -> 750 | BY6: {=IFERROR((AZ6+BH6*职业模板!$E$16)*(1+INDEX(职业模板!$C$34:$J$34,MATCH(X$3,职业模板!$C$28:$J$28,FALSE))+INDEX(职业模板!$C$60:$J$60,MATCH(X$3,职业模板!$C$39:$J$39,FALSE))),"")} -> 800 | BZ6: {=IFERROR((BA6+BI6*职业模板!$E$16)*(1+INDEX(职业模板!$C$34:$J$34,MATCH(Y$3,职业模板!$C$28:$J$28,FALSE))+INDEX(职业模板!$C$60:$J$60,MATCH(Y$3,职业模板!$C$39:$J$39,FALSE))),"")} -> 570 | CA6: {=IFERROR((BB6+BJ6*职业模板!$E$16)*(1+INDEX(职业模板!$C$34:$J$34,MATCH(Z$3,职业模板!$C$28:$J$28,FALSE))+INDEX(职业模板!$C$60:$J$60,MATCH(Z$3,职业模板!$C$39:$J$39,FALSE))),"")} -> 720 | CB6: {=IFERROR((BC6+BK6*职业模板!$E$16)*(1+INDEX(职业模板!$C$34:$J$34,MATCH(AA$3,职业模板!$C$28:$J$28,FALSE))+INDEX(职业模板!$C$60:$J$60,MATCH(AA$3,职业模板!$C$39:$J$39,FALSE))),"")} -> 175 | CC6: {=IFERROR((BD6+BL6*职业模板!$E$16)*(1+INDEX(职业模板!$C$34:$J$34,MATCH(AB$3,职业模板!$C$28:$J$28,FALSE))+INDEX(职业模板!$C$60:$J$60,MATCH(AB$3,职业模板!$C$39:$J$39,FALSE))),"")} -> 245 | CD6: {=IFERROR((BE6+BM6*职业模板!$E$16)*(1+INDEX(职业模板!$C$34:$J$34,MATCH(AC$3,职业模板!$C$28:$J$28,FALSE))+INDEX(职业模板!$C$60:$J$60,MATCH(AC$3,职业模板!$C$39:$J$39,FALSE))),"")} -> 210 | CE6: {=IF(SUMPRODUCT(BW6:CA6,属性分配!$C$7:$G$7)=0,"",SUMPRODUCT(BW6:CA6,属性分配!$C$7:$G$7))} -> 13460
